<robot name="RomeoH37">
    <material name="LightGrey">
        <texture />
        <color rgba="0.9 0.9 0.9 1" />
    </material>
    <link name="AccelerometerDownTorso_sensor" />
    <link name="AccelerometerHead_sensor" />
    <link name="CameraLeftEye_sensor" />
    <link name="CameraLeft_sensor" />
    <link name="CameraRightEye_sensor" />
    <link name="CameraRight_sensor" />
    <link name="GyrometerDownTorso_sensor" />
    <link name="GyrometerHead_sensor" />
    <link name="Head_effector" />
    <link name="LArm_effector" />
    <link name="LEye_effector" />
    <link name="LFinger11_link">
        <visual>
            <origin xyz="0 0 0" rpy="0 -0 0" />
            <geometry>
                <mesh filename="file:///usr/local/share/alrobotmodel/meshes/romeo/LFinger11.mesh" scale="1 1 1" />
            </geometry>
            <material name="LightGrey">
                <texture />
                <color rgba="0.9 0.9 0.9 1" />
            </material>
        </visual>
    </link>
    <link name="LFinger12_link">
        <visual>
            <origin xyz="0 0 0" rpy="0 -0 0" />
            <geometry>
                <mesh filename="file:///usr/local/share/alrobotmodel/meshes/romeo/LFinger12.mesh" scale="1 1 1" />
            </geometry>
            <material name="LightGrey">
                <texture />
                <color rgba="0.9 0.9 0.9 1" />
            </material>
        </visual>
    </link>
    <link name="LFinger13_link">
        <visual>
            <origin xyz="0 0 0" rpy="0 -0 0" />
            <geometry>
                <mesh filename="file:///usr/local/share/alrobotmodel/meshes/romeo/LFinger13.mesh" scale="1 1 1" />
            </geometry>
            <material name="LightGrey">
                <texture />
                <color rgba="0.9 0.9 0.9 1" />
            </material>
        </visual>
    </link>
    <link name="LFinger21_link">
        <visual>
            <origin xyz="0 0 0" rpy="0 -0 0" />
            <geometry>
                <mesh filename="file:///usr/local/share/alrobotmodel/meshes/romeo/LFinger21.mesh" scale="1 1 1" />
            </geometry>
            <material name="LightGrey">
                <texture />
                <color rgba="0.9 0.9 0.9 1" />
            </material>
        </visual>
    </link>
    <link name="LFinger22_link">
        <visual>
            <origin xyz="0 0 0" rpy="0 -0 0" />
            <geometry>
                <mesh filename="file:///usr/local/share/alrobotmodel/meshes/romeo/LFinger22.mesh" scale="1 1 1" />
            </geometry>
            <material name="LightGrey">
                <texture />
                <color rgba="0.9 0.9 0.9 1" />
            </material>
        </visual>
    </link>
    <link name="LFinger23_link">
        <visual>
            <origin xyz="0 0 0" rpy="0 -0 0" />
            <geometry>
                <mesh filename="file:///usr/local/share/alrobotmodel/meshes/romeo/LFinger23.mesh" scale="1 1 1" />
            </geometry>
            <material name="LightGrey">
                <texture />
                <color rgba="0.9 0.9 0.9 1" />
            </material>
        </visual>
    </link>
    <link name="LFinger31_link">
        <visual>
            <origin xyz="0 0 0" rpy="0 -0 0" />
            <geometry>
                <mesh filename="file:///usr/local/share/alrobotmodel/meshes/romeo/LFinger31.mesh" scale="1 1 1" />
            </geometry>
            <material name="LightGrey">
                <texture />
                <color rgba="0.9 0.9 0.9 1" />
            </material>
        </visual>
    </link>
    <link name="LFinger32_link">
        <visual>
            <origin xyz="0 0 0" rpy="0 -0 0" />
            <geometry>
                <mesh filename="file:///usr/local/share/alrobotmodel/meshes/romeo/LFinger32.mesh" scale="1 1 1" />
            </geometry>
            <material name="LightGrey">
                <texture />
                <color rgba="0.9 0.9 0.9 1" />
            </material>
        </visual>
    </link>
    <link name="LFinger33_link">
        <visual>
            <origin xyz="0 0 0" rpy="0 -0 0" />
            <geometry>
                <mesh filename="file:///usr/local/share/alrobotmodel/meshes/romeo/LFinger33.mesh" scale="1 1 1" />
            </geometry>
            <material name="LightGrey">
                <texture />
                <color rgba="0.9 0.9 0.9 1" />
            </material>
        </visual>
    </link>
    <link name="LFoot/FSR/CenterFront_sensor" />
    <link name="LFoot/FSR/CenterRear_sensor" />
    <link name="LFoot/FSR/HeelLeft_sensor" />
    <link name="LFoot/FSR/HeelRight_sensor" />
    <link name="LFoot/FSR/ToeFrontLeft_sensor" />
    <link name="LFoot/FSR/ToeFrontRight_sensor" />
    <link name="LFoot/FSR/ToeRearLeft_sensor" />
    <link name="LFoot/FSR/ToeRearRight_sensor" />
    <link name="LHand_actuator_frame" />
    <link name="LLeg_effector" />
    <link name="LThumb1_link">
        <visual>
            <origin xyz="0 0 0" rpy="0 -0 0" />
            <geometry>
                <mesh filename="file:///usr/local/share/alrobotmodel/meshes/romeo/LThumb1.mesh" scale="1 1 1" />
            </geometry>
            <material name="LightGrey">
                <texture />
                <color rgba="0.9 0.9 0.9 1" />
            </material>
        </visual>
    </link>
    <link name="LThumb2_link">
        <visual>
            <origin xyz="0 0 0" rpy="0 -0 0" />
            <geometry>
                <mesh filename="file:///usr/local/share/alrobotmodel/meshes/romeo/LThumb2.mesh" scale="1 1 1" />
            </geometry>
            <material name="LightGrey">
                <texture />
                <color rgba="0.9 0.9 0.9 1" />
            </material>
        </visual>
    </link>
    <link name="LThumb3_link">
        <visual>
            <origin xyz="0 0 0" rpy="0 -0 0" />
            <geometry>
                <mesh filename="file:///usr/local/share/alrobotmodel/meshes/romeo/LThumb3.mesh" scale="1 1 1" />
            </geometry>
            <material name="LightGrey">
                <texture />
                <color rgba="0.9 0.9 0.9 1" />
            </material>
        </visual>
    </link>
    <link name="RArm_effector" />
    <link name="REye_effector" />
    <link name="RFinger11_link">
        <visual>
            <origin xyz="0 0 0" rpy="0 -0 0" />
            <geometry>
                <mesh filename="file:///usr/local/share/alrobotmodel/meshes/romeo/RFinger11.mesh" scale="1 1 1" />
            </geometry>
            <material name="LightGrey">
                <texture />
                <color rgba="0.9 0.9 0.9 1" />
            </material>
        </visual>
    </link>
    <link name="RFinger12_link">
        <visual>
            <origin xyz="0 0 0" rpy="0 -0 0" />
            <geometry>
                <mesh filename="file:///usr/local/share/alrobotmodel/meshes/romeo/RFinger12.mesh" scale="1 1 1" />
            </geometry>
            <material name="LightGrey">
                <texture />
                <color rgba="0.9 0.9 0.9 1" />
            </material>
        </visual>
    </link>
    <link name="RFinger13_link">
        <visual>
            <origin xyz="0 0 0" rpy="0 -0 0" />
            <geometry>
                <mesh filename="file:///usr/local/share/alrobotmodel/meshes/romeo/RFinger13.mesh" scale="1 1 1" />
            </geometry>
            <material name="LightGrey">
                <texture />
                <color rgba="0.9 0.9 0.9 1" />
            </material>
        </visual>
    </link>
    <link name="RFinger21_link">
        <visual>
            <origin xyz="0 0 0" rpy="0 -0 0" />
            <geometry>
                <mesh filename="file:///usr/local/share/alrobotmodel/meshes/romeo/RFinger21.mesh" scale="1 1 1" />
            </geometry>
            <material name="LightGrey">
                <texture />
                <color rgba="0.9 0.9 0.9 1" />
            </material>
        </visual>
    </link>
    <link name="RFinger22_link">
        <visual>
            <origin xyz="0 0 0" rpy="0 -0 0" />
            <geometry>
                <mesh filename="file:///usr/local/share/alrobotmodel/meshes/romeo/RFinger22.mesh" scale="1 1 1" />
            </geometry>
            <material name="LightGrey">
                <texture />
                <color rgba="0.9 0.9 0.9 1" />
            </material>
        </visual>
    </link>
    <link name="RFinger23_link">
        <visual>
            <origin xyz="0 0 0" rpy="0 -0 0" />
            <geometry>
                <mesh filename="file:///usr/local/share/alrobotmodel/meshes/romeo/RFinger23.mesh" scale="1 1 1" />
            </geometry>
            <material name="LightGrey">
                <texture />
                <color rgba="0.9 0.9 0.9 1" />
            </material>
        </visual>
    </link>
    <link name="RFinger31_link">
        <visual>
            <origin xyz="0 0 0" rpy="0 -0 0" />
            <geometry>
                <mesh filename="file:///usr/local/share/alrobotmodel/meshes/romeo/RFinger31.mesh" scale="1 1 1" />
            </geometry>
            <material name="LightGrey">
                <texture />
                <color rgba="0.9 0.9 0.9 1" />
            </material>
        </visual>
    </link>
    <link name="RFinger32_link">
        <visual>
            <origin xyz="0 0 0" rpy="0 -0 0" />
            <geometry>
                <mesh filename="file:///usr/local/share/alrobotmodel/meshes/romeo/RFinger32.mesh" scale="1 1 1" />
            </geometry>
            <material name="LightGrey">
                <texture />
                <color rgba="0.9 0.9 0.9 1" />
            </material>
        </visual>
    </link>
    <link name="RFinger33_link">
        <visual>
            <origin xyz="0 0 0" rpy="0 -0 0" />
            <geometry>
                <mesh filename="file:///usr/local/share/alrobotmodel/meshes/romeo/RFinger33.mesh" scale="1 1 1" />
            </geometry>
            <material name="LightGrey">
                <texture />
                <color rgba="0.9 0.9 0.9 1" />
            </material>
        </visual>
    </link>
    <link name="RFoot/FSR/CenterFront_sensor" />
    <link name="RFoot/FSR/CenterRear_sensor" />
    <link name="RFoot/FSR/HeelLeft_sensor" />
    <link name="RFoot/FSR/HeelRight_sensor" />
    <link name="RFoot/FSR/ToeFrontLeft_sensor" />
    <link name="RFoot/FSR/ToeFrontRight_sensor" />
    <link name="RFoot/FSR/ToeRearLeft_sensor" />
    <link name="RFoot/FSR/ToeRearRight_sensor" />
    <link name="RHand_actuator_frame" />
    <link name="RLeg_effector" />
    <link name="RThumb1_link">
        <visual>
            <origin xyz="0 0 0" rpy="0 -0 0" />
            <geometry>
                <mesh filename="file:///usr/local/share/alrobotmodel/meshes/romeo/RThumb1.mesh" scale="1 1 1" />
            </geometry>
            <material name="LightGrey">
                <texture />
                <color rgba="0.9 0.9 0.9 1" />
            </material>
        </visual>
    </link>
    <link name="RThumb2_link">
        <visual>
            <origin xyz="0 0 0" rpy="0 -0 0" />
            <geometry>
                <mesh filename="file:///usr/local/share/alrobotmodel/meshes/romeo/RThumb2.mesh" scale="1 1 1" />
            </geometry>
            <material name="LightGrey">
                <texture />
                <color rgba="0.9 0.9 0.9 1" />
            </material>
        </visual>
    </link>
    <link name="RThumb3_link">
        <visual>
            <origin xyz="0 0 0" rpy="0 -0 0" />
            <geometry>
                <mesh filename="file:///usr/local/share/alrobotmodel/meshes/romeo/RThumb3.mesh" scale="1 1 1" />
            </geometry>
            <material name="LightGrey">
                <texture />
                <color rgba="0.9 0.9 0.9 1" />
            </material>
        </visual>
    </link>
    <link name="Torso_link">
        <inertial>
            <mass value="5.0541" />
            <origin xyz="0.01512 0 0.06743" rpy="0 -0 0" />
            <inertia ixx="0.0623514" ixy="-3.02711e-06" ixz="0.0093264" iyy="0.0365041" iyz="-0.000132541" izz="0.0639535" />
        </inertial>
        <visual>
            <origin xyz="0 0 0" rpy="0 -0 0" />
            <geometry>
                <mesh filename="file:///usr/local/share/alrobotmodel/meshes/romeo/Torso.mesh" scale="1 1 1" />
            </geometry>
            <material name="LightGrey">
                <texture />
                <color rgba="0.9 0.9 0.9 1" />
            </material>
        </visual>
    </link>
    <link name="NeckYaw_link">
        <inertial>
            <mass value="0.32745" />
            <origin xyz="-0.00635646 0 -0.030002" rpy="0 -0 0" />
            <inertia ixx="0.000242012" ixy="-2.69441e-07" ixz="-1.29328e-05" iyy="0.000225485" iyz="-6.99834e-07" izz="7.29248e-05" />
        </inertial>
    </link>
    <link name="NeckPitch_link">
        <inertial>
            <mass value="0.29923" />
            <origin xyz="0.00372 0 0.04811" rpy="0 -0 0" />
            <inertia ixx="0.000412832" ixy="-1.67846e-06" ixz="0.000111721" iyy="0.000383921" iyz="5.04259e-05" izz="0.000264006" />
        </inertial>
        <visual>
            <origin xyz="0 0 0" rpy="0 -0 0" />
            <geometry>
                <mesh filename="file:///usr/local/share/alrobotmodel/meshes/romeo/NeckPitch.mesh" scale="1 1 1" />
            </geometry>
            <material name="LightGrey">
                <texture />
                <color rgba="0.9 0.9 0.9 1" />
            </material>
        </visual>
    </link>
    <link name="HeadPitch_link">
        <inertial>
            <mass value="0.13728" />
            <origin xyz="0.0014 0 -0.00462" rpy="0 -0 0" />
            <inertia ixx="2.23022e-05" ixy="1.3103e-07" ixz="-1.31933e-05" iyy="6.44652e-05" iyz="-4.26e-09" izz="5.78637e-05" />
        </inertial>
    </link>
    <link name="HeadRoll_link">
        <inertial>
            <mass value="1.79432" />
            <origin xyz="0.01263 0 0.07498" rpy="0 -0 0" />
            <inertia ixx="0.00808695" ixy="-3.36239e-05" ixz="0.00239535" iyy="0.00960886" iyz="0.000260292" izz="0.00796332" />
        </inertial>
        <visual>
            <origin xyz="0 0 0" rpy="0 -0 0" />
            <geometry>
                <mesh filename="file:///usr/local/share/alrobotmodel/meshes/romeo/HeadRoll.mesh" scale="1 1 1" />
            </geometry>
            <material name="LightGrey">
                <texture />
                <color rgba="0.9 0.9 0.9 1" />
            </material>
        </visual>
    </link>
    <link name="LEyeYaw_link">
        <inertial>
            <mass value="0.01" />
            <origin xyz="0 0 0" rpy="0 -0 0" />
            <inertia ixx="0" ixy="0" ixz="0" iyy="0" iyz="0" izz="0" />
        </inertial>
    </link>
    <link name="LEyePitch_link">
        <inertial>
            <mass value="0.01" />
            <origin xyz="0 0 0" rpy="0 -0 0" />
            <inertia ixx="0" ixy="0" ixz="0" iyy="0" iyz="0" izz="0" />
        </inertial>
        <visual>
            <origin xyz="0 0 0" rpy="0 -0 0" />
            <geometry>
                <mesh filename="file:///usr/local/share/alrobotmodel/meshes/romeo/LEye.mesh" scale="1 1 1" />
            </geometry>
            <material name="LightGrey">
                <texture />
                <color rgba="0.9 0.9 0.9 1" />
            </material>
        </visual>
    </link>
    <link name="REyeYaw_link">
        <inertial>
            <mass value="0.01" />
            <origin xyz="0 0 0" rpy="0 -0 0" />
            <inertia ixx="0" ixy="0" ixz="0" iyy="0" iyz="0" izz="0" />
        </inertial>
    </link>
    <link name="REyePitch_link">
        <inertial>
            <mass value="0.01" />
            <origin xyz="0 0 0" rpy="0 -0 0" />
            <inertia ixx="0" ixy="0" ixz="0" iyy="0" iyz="0" izz="0" />
        </inertial>
        <visual>
            <origin xyz="0 0 0" rpy="0 -0 0" />
            <geometry>
                <mesh filename="file:///usr/local/share/alrobotmodel/meshes/romeo/REye.mesh" scale="1 1 1" />
            </geometry>
            <material name="LightGrey">
                <texture />
                <color rgba="0.9 0.9 0.9 1" />
            </material>
        </visual>
    </link>
    <link name="LShoulderPitch_link">
        <inertial>
            <mass value="0.43527" />
            <origin xyz="-0.0112798 -0.0260712 0.00468882" rpy="0 -0 0" />
            <inertia ixx="0.000268738" ixy="-7.98278e-05" ixz="8.02495e-06" iyy="0.000151197" iyz="1.72313e-05" izz="0.000290161" />
        </inertial>
    </link>
    <link name="LShoulderYaw_link">
        <inertial>
            <mass value="0.69262" />
            <origin xyz="0.0965281 0.00465308 0.00168775" rpy="0 -0 0" />
            <inertia ixx="0.000953111" ixy="0.000479248" ixz="0.000898232" iyy="0.00250956" iyz="-1.65544e-05" izz="0.00233103" />
        </inertial>
        <visual>
            <origin xyz="0 0 0" rpy="0 -0 0" />
            <geometry>
                <mesh filename="file:///usr/local/share/alrobotmodel/meshes/romeo/LShoulderYaw.mesh" scale="1 1 1" />
            </geometry>
            <material name="LightGrey">
                <texture />
                <color rgba="0.9 0.9 0.9 1" />
            </material>
        </visual>
    </link>
    <link name="LElbowRoll_link">
        <inertial>
            <mass value="0.48271" />
            <origin xyz="-0.0348859 -0.0011589 -0.00148134" rpy="0 -0 0" />
            <inertia ixx="0.000166894" ixy="9.68978e-06" ixz="-1.49781e-05" iyy="0.000408141" iyz="1.2555e-06" izz="0.00036684" />
        </inertial>
    </link>
    <link name="LElbowYaw_link">
        <inertial>
            <mass value="0.36997" />
            <origin xyz="0.068523 0.0097 0.00458766" rpy="0 -0 0" />
            <inertia ixx="0.000404839" ixy="0.000470943" ixz="2.57237e-05" iyy="0.00102723" iyz="2.9528e-05" izz="0.000987329" />
        </inertial>
        <visual>
            <origin xyz="0 0 0" rpy="0 -0 0" />
            <geometry>
                <mesh filename="file:///usr/local/share/alrobotmodel/meshes/romeo/LElbowYaw.mesh" scale="1 1 1" />
            </geometry>
            <material name="LightGrey">
                <texture />
                <color rgba="0.9 0.9 0.9 1" />
            </material>
        </visual>
    </link>
    <link name="LWristRoll_link">
        <inertial>
            <mass value="0.17551" />
            <origin xyz="-0.0592449 6e-05 -0.00144745" rpy="0 -0 0" />
            <inertia ixx="8.1046e-05" ixy="-1.46219e-06" ixz="-3.67139e-05" iyy="0.000308979" iyz="-8.92509e-08" izz="0.000294305" />
        </inertial>
        <visual>
            <origin xyz="0 0 0" rpy="0 -0 0" />
            <geometry>
                <mesh filename="file:///usr/local/share/alrobotmodel/meshes/romeo/LWristRoll.mesh" scale="1 1 1" />
            </geometry>
            <material name="LightGrey">
                <texture />
                <color rgba="0.9 0.9 0.9 1" />
            </material>
        </visual>
    </link>
    <link name="LWristYaw_link">
        <inertial>
            <mass value="0.061" />
            <origin xyz="-0.00657144 0.00017 -0.000115829" rpy="0 -0 0" />
            <inertia ixx="1.25161e-05" ixy="-4.16668e-08" ixz="-7.01768e-07" iyy="2.83374e-05" iyz="1.56375e-08" izz="2.79694e-05" />
        </inertial>
        <visual>
            <origin xyz="0 0 0" rpy="0 -0 0" />
            <geometry>
                <mesh filename="file:///usr/local/share/alrobotmodel/meshes/romeo/LWristYaw.mesh" scale="1 1 1" />
            </geometry>
            <material name="LightGrey">
                <texture />
                <color rgba="0.9 0.9 0.9 1" />
            </material>
        </visual>
    </link>
    <link name="LWristPitch_link">
        <inertial>
            <mass value="0.35549" />
            <origin xyz="0.07358 -0.00628 -0.00098" rpy="0 -0 0" />
            <inertia ixx="0.000325271" ixy="-0.000324985" ixz="1.52493e-05" iyy="0.000666741" iyz="6.27901e-05" izz="0.000820118" />
        </inertial>
        <visual>
            <origin xyz="0 0 0" rpy="0 -0 0" />
            <geometry>
                <mesh filename="file:///usr/local/share/alrobotmodel/meshes/romeo/LWristPitch.mesh" scale="1 1 1" />
            </geometry>
            <material name="LightGrey">
                <texture />
                <color rgba="0.9 0.9 0.9 1" />
            </material>
        </visual>
    </link>
    <link name="TrunkYaw_link">
        <inertial>
            <mass value="4.4142" />
            <origin xyz="0.02825 0 -0.16653" rpy="0 -0 0" />
            <inertia ixx="0.0487058" ixy="6.27009e-05" ixz="-0.0496477" iyy="0.0449798" iyz="-2.92721e-05" izz="0.0182883" />
        </inertial>
        <visual>
            <origin xyz="0 0 0" rpy="0 -0 0" />
            <geometry>
                <mesh filename="file:///usr/local/share/alrobotmodel/meshes/romeo/TrunkYaw.mesh" scale="1 1 1" />
            </geometry>
            <material name="LightGrey">
                <texture />
                <color rgba="0.9 0.9 0.9 1" />
            </material>
        </visual>
    </link>
    <link name="LHipYaw_link">
        <inertial>
            <mass value="0.51527" />
            <origin xyz="-0.00922 -0.00167 0.042" rpy="0 -0 0" />
            <inertia ixx="0.000797373" ixy="-1.0184e-06" ixz="-0.000231697" iyy="0.00131776" iyz="3.91707e-06" izz="0.000785018" />
        </inertial>
    </link>
    <link name="LHipRoll_link">
        <inertial>
            <mass value="0.65864" />
            <origin xyz="0.00249 -0.00205 -0.00147" rpy="0 -0 0" />
            <inertia ixx="0.000863659" ixy="-6.20354e-06" ixz="-1.86793e-06" iyy="0.000505068" iyz="1.24373e-06" izz="0.000938555" />
        </inertial>
    </link>
    <link name="LHipPitch_link">
        <inertial>
            <mass value="4.34097" />
            <origin xyz="-0.02138 -0.00255 -0.14577" rpy="0 -0 0" />
            <inertia ixx="0.036002" ixy="-2.22796e-05" ixz="0.0230461" iyy="0.0364084" iyz="0.00065633" izz="0.0112971" />
        </inertial>
        <visual>
            <origin xyz="0 0 0" rpy="0 -0 0" />
            <geometry>
                <mesh filename="file:///usr/local/share/alrobotmodel/meshes/romeo/LHipPitch.mesh" scale="1 1 1" />
            </geometry>
            <material name="LightGrey">
                <texture />
                <color rgba="0.9 0.9 0.9 1" />
            </material>
        </visual>
    </link>
    <link name="LKneePitch_link">
        <inertial>
            <mass value="2.50906" />
            <origin xyz="-0.00415 -0.00054 -0.11011" rpy="0 -0 0" />
            <inertia ixx="0.0146626" ixy="5.06229e-08" ixz="0.00278247" iyy="0.0145661" iyz="-5.66452e-06" izz="0.00340234" />
        </inertial>
        <visual>
            <origin xyz="0 0 0" rpy="0 -0 0" />
            <geometry>
                <mesh filename="file:///usr/local/share/alrobotmodel/meshes/romeo/LKneePitch.mesh" scale="1 1 1" />
            </geometry>
            <material name="LightGrey">
                <texture />
                <color rgba="0.9 0.9 0.9 1" />
            </material>
        </visual>
    </link>
    <link name="LAnklePitch_link">
        <inertial>
            <mass value="0.42803" />
            <origin xyz="0.00132 -0.00117 0.00015" rpy="0 -0 0" />
            <inertia ixx="0.000338486" ixy="-1.0818e-07" ixz="9.621e-08" iyy="0.000220504" iyz="-1.13514e-06" izz="0.00039211" />
        </inertial>
    </link>
    <link name="LAnkleRoll_link">
        <inertial>
            <mass value="0.98379" />
            <origin xyz="0.0483878 0.00120158 -0.0367645" rpy="0 -0 0" />
            <inertia ixx="0.000901343" ixy="-4.5809e-05" ixz="-0.000810091" iyy="0.00540559" iyz="5.65123e-05" izz="0.00543292" />
        </inertial>
        <visual>
            <origin xyz="0 0 0" rpy="0 -0 0" />
            <geometry>
                <mesh filename="file:///usr/local/share/alrobotmodel/meshes/romeo/LAnkleRollBasic.mesh" scale="1 1 1" />
            </geometry>
            <material name="LightGrey">
                <texture />
                <color rgba="0.9 0.9 0.9 1" />
            </material>
        </visual>
    </link>
    <link name="RHipYaw_link">
        <inertial>
            <mass value="0.51527" />
            <origin xyz="-0.00922 0.00167 0.042" rpy="0 -0 0" />
            <inertia ixx="0.000797373" ixy="-1.6886e-05" ixz="-0.000231697" iyy="0.00131776" iyz="7.61991e-05" izz="0.000785018" />
        </inertial>
    </link>
    <link name="RHipRoll_link">
        <inertial>
            <mass value="0.65864" />
            <origin xyz="0.00249 0.00205 -0.00147" rpy="0 -0 0" />
            <inertia ixx="0.000863659" ixy="5.20518e-07" ixz="-1.86793e-06" iyy="0.000505068" iyz="-2.72589e-06" izz="0.000938555" />
        </inertial>
    </link>
    <link name="RHipPitch_link">
        <inertial>
            <mass value="4.34097" />
            <origin xyz="-0.02138 0.00255 -0.14577" rpy="0 -0 0" />
            <inertia ixx="0.036002" ixy="-0.00049561" ixz="0.0230461" iyy="0.0364084" iyz="-0.00257086" izz="0.0112971" />
        </inertial>
        <visual>
            <origin xyz="0 0 0" rpy="0 -0 0" />
            <geometry>
                <mesh filename="file:///usr/local/share/alrobotmodel/meshes/romeo/RHipPitch.mesh" scale="1 1 1" />
            </geometry>
            <material name="LightGrey">
                <texture />
                <color rgba="0.9 0.9 0.9 1" />
            </material>
        </visual>
    </link>
    <link name="RKneePitch_link">
        <inertial>
            <mass value="2.50906" />
            <origin xyz="-0.00415 0.00054 -0.11011" rpy="0 -0 0" />
            <inertia ixx="0.0146626" ixy="-1.1195e-05" ixz="0.00278247" iyy="0.0145661" iyz="-0.000304039" izz="0.00340234" />
        </inertial>
        <visual>
            <origin xyz="0 0 0" rpy="0 -0 0" />
            <geometry>
                <mesh filename="file:///usr/local/share/alrobotmodel/meshes/romeo/RKneePitch.mesh" scale="1 1 1" />
            </geometry>
            <material name="LightGrey">
                <texture />
                <color rgba="0.9 0.9 0.9 1" />
            </material>
        </visual>
    </link>
    <link name="RAnklePitch_link">
        <inertial>
            <mass value="0.42803" />
            <origin xyz="0.00132 0.00117 0.00015" rpy="0 -0 0" />
            <inertia ixx="0.000338486" ixy="1.21392e-06" ixz="9.621e-08" iyy="0.000220504" iyz="-9.84901e-07" izz="0.00039211" />
        </inertial>
    </link>
    <link name="RAnkleRoll_link">
        <inertial>
            <mass value="0.98379" />
            <origin xyz="0.0483878 -0.00120158 -0.0367645" rpy="0 -0 0" />
            <inertia ixx="0.000901343" ixy="-0.000160208" ixz="-0.000810091" iyy="0.00540559" iyz="0.000143431" izz="0.00543292" />
        </inertial>
        <visual>
            <origin xyz="0 0 0" rpy="0 -0 0" />
            <geometry>
                <mesh filename="file:///usr/local/share/alrobotmodel/meshes/romeo/RAnkleRollBasic.mesh" scale="1 1 1" />
            </geometry>
            <material name="LightGrey">
                <texture />
                <color rgba="0.9 0.9 0.9 1" />
            </material>
        </visual>
    </link>
    <link name="RShoulderPitch_link">
        <inertial>
            <mass value="0.43527" />
            <origin xyz="-0.0112798 0.0260712 0.00468882" rpy="0 -0 0" />
            <inertia ixx="0.000264235" ixy="8.24341e-05" ixz="1.55448e-05" iyy="0.000160752" iyz="-3.06968e-05" izz="0.000285109" />
        </inertial>
    </link>
    <link name="RShoulderYaw_link">
        <inertial>
            <mass value="0.69262" />
            <origin xyz="0.0965281 -0.00465308 0.00168775" rpy="0 -0 0" />
            <inertia ixx="0.000955527" ixy="-0.000291705" ixz="0.000927729" iyy="0.00250758" iyz="1.49948e-05" izz="0.00233059" />
        </inertial>
        <visual>
            <origin xyz="0 0 0" rpy="0 -0 0" />
            <geometry>
                <mesh filename="file:///usr/local/share/alrobotmodel/meshes/romeo/RShoulderYaw.mesh" scale="1 1 1" />
            </geometry>
            <material name="LightGrey">
                <texture />
                <color rgba="0.9 0.9 0.9 1" />
            </material>
        </visual>
    </link>
    <link name="RElbowRoll_link">
        <inertial>
            <mass value="0.48271" />
            <origin xyz="-0.0348859 0.0011589 -0.00148134" rpy="0 -0 0" />
            <inertia ixx="0.000166993" ixy="-6.12728e-06" ixz="-1.49476e-05" iyy="0.000408038" iyz="7.67117e-07" izz="0.000366843" />
        </inertial>
    </link>
    <link name="RElbowYaw_link">
        <inertial>
            <mass value="0.36997" />
            <origin xyz="0.068523 -0.0097 0.00458766" rpy="0 -0 0" />
            <inertia ixx="0.000404839" ixy="-2.08748e-05" ixz="2.57237e-05" iyy="0.00102723" iyz="-3.39957e-06" izz="0.000987329" />
        </inertial>
        <visual>
            <origin xyz="0 0 0" rpy="0 -0 0" />
            <geometry>
                <mesh filename="file:///usr/local/share/alrobotmodel/meshes/romeo/RElbowYaw.mesh" scale="1 1 1" />
            </geometry>
            <material name="LightGrey">
                <texture />
                <color rgba="0.9 0.9 0.9 1" />
            </material>
        </visual>
    </link>
    <link name="RWristRoll_link">
        <inertial>
            <mass value="0.17551" />
            <origin xyz="-0.0592449 -6e-05 -0.00144745" rpy="0 -0 0" />
            <inertia ixx="8.1046e-05" ixy="-2.14425e-07" ixz="-3.67139e-05" iyy="0.000308979" iyz="-5.87658e-08" izz="0.000294305" />
        </inertial>
        <visual>
            <origin xyz="0 0 0" rpy="0 -0 0" />
            <geometry>
                <mesh filename="file:///usr/local/share/alrobotmodel/meshes/romeo/RWristRoll.mesh" scale="1 1 1" />
            </geometry>
            <material name="LightGrey">
                <texture />
                <color rgba="0.9 0.9 0.9 1" />
            </material>
        </visual>
    </link>
    <link name="RWristYaw_link">
        <inertial>
            <mass value="0.061" />
            <origin xyz="-0.00657144 -0.00017 -0.000115829" rpy="0 -0 0" />
            <inertia ixx="1.25161e-05" ixy="9.4625e-08" ixz="-7.01768e-07" iyy="2.83374e-05" iyz="1.80397e-08" izz="2.79694e-05" />
        </inertial>
        <visual>
            <origin xyz="0 0 0" rpy="0 -0 0" />
            <geometry>
                <mesh filename="file:///usr/local/share/alrobotmodel/meshes/romeo/RWristYaw.mesh" scale="1 1 1" />
            </geometry>
            <material name="LightGrey">
                <texture />
                <color rgba="0.9 0.9 0.9 1" />
            </material>
        </visual>
    </link>
    <link name="RWristPitch_link">
        <inertial>
            <mass value="0.35549" />
            <origin xyz="0.07358 0.00628 -0.00098" rpy="0 -0 0" />
            <inertia ixx="0.000325271" ixy="3.54589e-06" ixz="1.52493e-05" iyy="0.000666741" iyz="5.84145e-05" izz="0.000820118" />
        </inertial>
        <visual>
            <origin xyz="0 0 0" rpy="0 -0 0" />
            <geometry>
                <mesh filename="file:///usr/local/share/alrobotmodel/meshes/romeo/RWristPitch.mesh" scale="1 1 1" />
            </geometry>
            <material name="LightGrey">
                <texture />
                <color rgba="0.9 0.9 0.9 1" />
            </material>
        </visual>
    </link>
    <link name="Trunk_effector" />
    <link name="base_link" />
    <joint name="AccelerometerDownTorso_sensor_fixedjoint" type="fixed">
        <origin xyz="0.06185 0.0087 -0.1582" rpy="0 -0 0" />
        <axis xyz="0 0 0" />
        <parent link="TrunkYaw_link" />
        <child link="AccelerometerDownTorso_sensor" />
    </joint>
    <joint name="AccelerometerHead_sensor_fixedjoint" type="fixed">
        <origin xyz="-0.01135 -0.04225 0.16011" rpy="0 -0 1.5708" />
        <axis xyz="0 0 0" />
        <parent link="HeadRoll_link" />
        <child link="AccelerometerHead_sensor" />
    </joint>
    <joint name="CameraLeftEye_sensor_fixedjoint" type="fixed">
        <origin xyz="0.01299 0 0" rpy="0 -0 0" />
        <axis xyz="0 0 0" />
        <parent link="LEyePitch_link" />
        <child link="CameraLeftEye_sensor" />
    </joint>
    <joint name="CameraLeft_sensor_fixedjoint" type="fixed">
        <origin xyz="0.11229 0.04 0.09938" rpy="0 -0 0" />
        <axis xyz="0 0 0" />
        <parent link="HeadRoll_link" />
        <child link="CameraLeft_sensor" />
    </joint>
    <joint name="CameraRightEye_sensor_fixedjoint" type="fixed">
        <origin xyz="0.01299 0 0" rpy="0 -0 0" />
        <axis xyz="0 0 0" />
        <parent link="REyePitch_link" />
        <child link="CameraRightEye_sensor" />
    </joint>
    <joint name="CameraRight_sensor_fixedjoint" type="fixed">
        <origin xyz="0.11229 -0.04 0.09938" rpy="0 -0 0" />
        <axis xyz="0 0 0" />
        <parent link="HeadRoll_link" />
        <child link="CameraRight_sensor" />
    </joint>
    <joint name="GyrometerDownTorso_sensor_fixedjoint" type="fixed">
        <origin xyz="0.06185 0.0087 -0.1582" rpy="0 -0 0" />
        <axis xyz="0 0 0" />
        <parent link="TrunkYaw_link" />
        <child link="GyrometerDownTorso_sensor" />
    </joint>
    <joint name="GyrometerHead_sensor_fixedjoint" type="fixed">
        <origin xyz="-0.01135 -0.04225 0.16011" rpy="0 -0 1.5708" />
        <axis xyz="0 0 0" />
        <parent link="HeadRoll_link" />
        <child link="GyrometerHead_sensor" />
    </joint>
    <joint name="Head_effector_fixedjoint" type="fixed">
        <origin xyz="0 0 0" rpy="0 -0 0" />
        <axis xyz="0 0 0" />
        <parent link="HeadRoll_link" />
        <child link="Head_effector" />
    </joint>
    <joint name="LArm_effector_fixedjoint" type="fixed">
        <origin xyz="0 0 0" rpy="0 -0 0" />
        <axis xyz="0 0 0" />
        <parent link="LWristPitch_link" />
        <child link="LArm_effector" />
    </joint>
    <joint name="LEye_effector_fixedjoint" type="fixed">
        <origin xyz="0 0 0" rpy="0 -0 0" />
        <axis xyz="0 0 0" />
        <parent link="LEyePitch_link" />
        <child link="LEye_effector" />
    </joint>
    <joint name="LFinger11_joint" type="continuous">
        <origin xyz="0.12385 -0.03024 0.00999" rpy="1.69304 1.5708 3.14159" />
        <axis xyz="0 0 1" />
        <parent link="LWristPitch_link" />
        <child link="LFinger11_link" />
        <mimic offset="0" multiplier="0.988205" joint="LHand_actuator" />
    </joint>
    <joint name="LFinger12_joint" type="continuous">
        <origin xyz="0 -0.0230929 -4.02331e-06" rpy="0 -0 0" />
        <axis xyz="0 0 1" />
        <parent link="LFinger11_link" />
        <child link="LFinger12_link" />
        <mimic offset="0" multiplier="0.988205" joint="LHand_actuator" />
    </joint>
    <joint name="LFinger13_joint" type="continuous">
        <origin xyz="0 -0.0230916 5.90086e-06" rpy="0 -0 0" />
        <axis xyz="0 0 1" />
        <parent link="LFinger12_link" />
        <child link="LFinger13_link" />
        <mimic offset="0" multiplier="0.988205" joint="LHand_actuator" />
    </joint>
    <joint name="LFinger21_joint" type="continuous">
        <origin xyz="0.12934 0 0.01499" rpy="1.5708 1.5708 3.14159" />
        <axis xyz="0 0 1" />
        <parent link="LWristPitch_link" />
        <child link="LFinger21_link" />
        <mimic offset="0" multiplier="0.988205" joint="LHand_actuator" />
    </joint>
    <joint name="LFinger22_joint" type="continuous">
        <origin xyz="0 -0.02309 0" rpy="0 -0 0" />
        <axis xyz="0 0 1" />
        <parent link="LFinger21_link" />
        <child link="LFinger22_link" />
        <mimic offset="0" multiplier="0.988205" joint="LHand_actuator" />
    </joint>
    <joint name="LFinger23_joint" type="continuous">
        <origin xyz="0 -0.02309 0" rpy="0 -0 0" />
        <axis xyz="0 0 1" />
        <parent link="LFinger22_link" />
        <child link="LFinger23_link" />
        <mimic offset="0" multiplier="0.988205" joint="LHand_actuator" />
    </joint>
    <joint name="LFinger31_joint" type="continuous">
        <origin xyz="0.11215 0.03024 0.00999" rpy="1.69304 -1.5708 3.14159" />
        <axis xyz="0 0 1" />
        <parent link="LWristPitch_link" />
        <child link="LFinger31_link" />
        <mimic offset="0" multiplier="0.988205" joint="LHand_actuator" />
    </joint>
    <joint name="LFinger32_joint" type="continuous">
        <origin xyz="0 0.0230928 4.02331e-06" rpy="0 -0 0" />
        <axis xyz="0 0 1" />
        <parent link="LFinger31_link" />
        <child link="LFinger32_link" />
        <mimic offset="0" multiplier="0.988205" joint="LHand_actuator" />
    </joint>
    <joint name="LFinger33_joint" type="continuous">
        <origin xyz="0 0.0230916 -5.91576e-06" rpy="0 -0 0" />
        <axis xyz="0 0 1" />
        <parent link="LFinger32_link" />
        <child link="LFinger33_link" />
        <mimic offset="0" multiplier="0.988205" joint="LHand_actuator" />
    </joint>
    <joint name="LFoot/FSR/CenterFront_sensor_fixedjoint" type="fixed">
        <origin xyz="0.07498 0.01275 -0.06226" rpy="0 -0 0" />
        <axis xyz="0 0 0" />
        <parent link="LAnkleRoll_link" />
        <child link="LFoot/FSR/CenterFront_sensor" />
    </joint>
    <joint name="LFoot/FSR/CenterRear_sensor_fixedjoint" type="fixed">
        <origin xyz="0.01448 0.0145 -0.06226" rpy="0 -0 0" />
        <axis xyz="0 0 0" />
        <parent link="LAnkleRoll_link" />
        <child link="LFoot/FSR/CenterRear_sensor" />
    </joint>
    <joint name="LFoot/FSR/HeelLeft_sensor_fixedjoint" type="fixed">
        <origin xyz="-0.04602 0.017 -0.06226" rpy="0 -0 0" />
        <axis xyz="0 0 0" />
        <parent link="LAnkleRoll_link" />
        <child link="LFoot/FSR/HeelLeft_sensor" />
    </joint>
    <joint name="LFoot/FSR/HeelRight_sensor_fixedjoint" type="fixed">
        <origin xyz="-0.04602 -0.017 -0.06226" rpy="0 -0 0" />
        <axis xyz="0 0 0" />
        <parent link="LAnkleRoll_link" />
        <child link="LFoot/FSR/HeelRight_sensor" />
    </joint>
    <joint name="LFoot/FSR/ToeFrontLeft_sensor_fixedjoint" type="fixed">
        <origin xyz="0.16098 0.024 -0.06226" rpy="0 -0 0" />
        <axis xyz="0 0 0" />
        <parent link="LAnkleRoll_link" />
        <child link="LFoot/FSR/ToeFrontLeft_sensor" />
    </joint>
    <joint name="LFoot/FSR/ToeFrontRight_sensor_fixedjoint" type="fixed">
        <origin xyz="0.17298 -0.023 -0.06226" rpy="0 -0 0" />
        <axis xyz="0 0 0" />
        <parent link="LAnkleRoll_link" />
        <child link="LFoot/FSR/ToeFrontRight_sensor" />
    </joint>
    <joint name="LFoot/FSR/ToeRearLeft_sensor_fixedjoint" type="fixed">
        <origin xyz="0.11898 0.0335 -0.06226" rpy="0 -0 0" />
        <axis xyz="0 0 0" />
        <parent link="LAnkleRoll_link" />
        <child link="LFoot/FSR/ToeRearLeft_sensor" />
    </joint>
    <joint name="LFoot/FSR/ToeRearRight_sensor_fixedjoint" type="fixed">
        <origin xyz="0.12698 -0.0315 -0.06226" rpy="0 -0 0" />
        <axis xyz="0 0 0" />
        <parent link="LAnkleRoll_link" />
        <child link="LFoot/FSR/ToeRearRight_sensor" />
    </joint>
    <joint name="LHand_actuator" type="revolute">
        <origin xyz="-0.0579412 -0.0159 -0.00260997" rpy="1.5708 0.0450146 -3.14159" />
        <axis xyz="1 0 0" />
        <parent link="LWristPitch_link" />
        <child link="LHand_actuator_frame" />
        <limit effort="0.649997" velocity="59.8925" lower="0" upper="1" />
    </joint>
    <joint name="LLeg_effector_fixedjoint" type="fixed">
        <origin xyz="0 0 -0.0651" rpy="0 -0 0" />
        <axis xyz="0 0 0" />
        <parent link="LAnkleRoll_link" />
        <child link="LLeg_effector" />
    </joint>
    <joint name="LThumb1_joint" type="continuous">
        <origin xyz="0.0624 -0.03131 -0.00574" rpy="-2.97779 1.21665 -3.14159" />
        <axis xyz="0 0 1" />
        <parent link="LWristPitch_link" />
        <child link="LThumb1_link" />
        <mimic offset="0" multiplier="1.74533" joint="LHand_actuator" />
    </joint>
    <joint name="LThumb2_joint" type="continuous">
        <origin xyz="0.000329241 -0.0388865 0.017011" rpy="1.13316 7.45058e-09 -1.80698" />
        <axis xyz="0 0 1" />
        <parent link="LThumb1_link" />
        <child link="LThumb2_link" />
        <mimic offset="0" multiplier="0.988205" joint="LHand_actuator" />
    </joint>
    <joint name="LThumb3_joint" type="continuous">
        <origin xyz="0.0187362 0.0135152 5.21541e-06" rpy="-5.96047e-08 -0 1.49012e-08" />
        <axis xyz="0 0 1" />
        <parent link="LThumb2_link" />
        <child link="LThumb3_link" />
        <mimic offset="0" multiplier="0.988205" joint="LHand_actuator" />
    </joint>
    <joint name="NeckYaw_joint" type="revolute">
        <origin xyz="0.0548 0 0.1675" rpy="0 -2.98023e-08 0" />
        <axis xyz="0.173651 0 0.984807" />
        <parent link="Torso_link" />
        <child link="NeckYaw_link" />
        <limit effort="7.324" velocity="4" lower="-2.0595" upper="2.0595" />
    </joint>
    <joint name="NeckPitch_joint" type="revolute">
        <origin xyz="0 0 0" rpy="0 -2.98023e-08 0" />
        <axis xyz="0 1 0" />
        <parent link="NeckYaw_link" />
        <child link="NeckPitch_link" />
        <limit effort="5.956" velocity="2.2" lower="-0.3142" upper="0.6632" />
    </joint>
    <joint name="HeadPitch_joint" type="revolute">
        <origin xyz="0 0 0.0951" rpy="0 -0 0" />
        <axis xyz="0 1 0" />
        <parent link="NeckPitch_link" />
        <child link="HeadPitch_link" />
        <limit effort="2.57" velocity="1.9" lower="-0.2571" upper="0.2971" />
    </joint>
    <joint name="HeadRoll_joint" type="revolute">
        <origin xyz="0 0 0" rpy="0 -0 0" />
        <axis xyz="1 0 0" />
        <parent link="HeadPitch_link" />
        <child link="HeadRoll_link" />
        <limit effort="3.748" velocity="1.5" lower="-0.4887" upper="0.4887" />
    </joint>
    <joint name="LEyeYaw_joint" type="revolute">
        <origin xyz="0.08948 0.03192 0.05425" rpy="0 -0 0" />
        <axis xyz="0 0 1" />
        <parent link="HeadRoll_link" />
        <child link="LEyeYaw_link" />
        <limit effort="0.01752" velocity="293.215" lower="-0.523599" upper="0.523599" />
    </joint>
    <joint name="LEyePitch_joint" type="revolute">
        <origin xyz="0 0 0" rpy="0 -0 0" />
        <axis xyz="0 1 0" />
        <parent link="LEyeYaw_link" />
        <child link="LEyePitch_link" />
        <limit effort="0.01752" velocity="293.215" lower="-0.349066" upper="0.349066" />
    </joint>
    <joint name="REyeYaw_joint" type="revolute">
        <origin xyz="0.08948 -0.03192 0.05425" rpy="0 -0 0" />
        <axis xyz="0 0 1" />
        <parent link="HeadRoll_link" />
        <child link="REyeYaw_link" />
        <limit effort="0.01752" velocity="293.215" lower="-0.523599" upper="0.523599" />
    </joint>
    <joint name="REyePitch_joint" type="revolute">
        <origin xyz="0 0 0" rpy="0 -0 0" />
        <axis xyz="0 1 0" />
        <parent link="REyeYaw_link" />
        <child link="REyePitch_link" />
        <limit effort="0.01752" velocity="293.215" lower="-0.349066" upper="0.349066" />
    </joint>
    <joint name="LShoulderPitch_joint" type="revolute">
        <origin xyz="0.049862 0.19 0.073851" rpy="1.49012e-08 7.45058e-09 0" />
        <axis xyz="0.417025 0.895055 -0.15801" />
        <parent link="Torso_link" />
        <child link="LShoulderPitch_link" />
        <limit effort="19.095" velocity="2.2" lower="-1.3491" upper="2.2462" />
    </joint>
    <joint name="LShoulderYaw_joint" type="revolute">
        <origin xyz="0 0 0" rpy="2.98023e-08 1.11759e-08 -5.58793e-08" />
        <axis xyz="0.0401398 0.155542 0.987013" />
        <parent link="LShoulderPitch_link" />
        <child link="LShoulderYaw_link" />
        <limit effort="9.031" velocity="4" lower="-0.5768" upper="0.9242" />
    </joint>
    <joint name="LElbowRoll_joint" type="revolute">
        <origin xyz="0.210824 7.40511e-09 -0.008631" rpy="-2.56114e-09 -0 -9.31322e-09" />
        <axis xyz="0.998889 0.0139984 0.044995" />
        <parent link="LShoulderYaw_link" />
        <child link="LElbowRoll_link" />
        <limit effort="7.404" velocity="3.7" lower="-2.2148" upper="1.9042" />
    </joint>
    <joint name="LElbowYaw_joint" type="revolute">
        <origin xyz="0 0 0" rpy="-1.49504e-08 -1.86264e-08 2.12577e-09" />
        <axis xyz="-0.0449994 0 0.998987" />
        <parent link="LElbowRoll_link" />
        <child link="LElbowYaw_link" />
        <limit effort="6.02" velocity="4" lower="-1.5228" upper="0.0044" />
    </joint>
    <joint name="LWristRoll_joint" type="revolute">
        <origin xyz="0.190404 -4.65661e-10 0.008631" rpy="1.6234e-11 -7.45058e-09 9.32998e-10" />
        <axis xyz="0.998987 0 0.0449994" />
        <parent link="LElbowYaw_link" />
        <child link="LWristRoll_link" />
        <limit effort="2.177" velocity="1.1" lower="-3.6303" upper="0.4887" />
    </joint>
    <joint name="LWristYaw_joint" type="revolute">
        <origin xyz="0 0 0" rpy="0 -0 0" />
        <axis xyz="-0.0449994 0 0.998987" />
        <parent link="LWristRoll_link" />
        <child link="LWristYaw_link" />
        <limit effort="0.862" velocity="2.26" lower="-0.4014" upper="0.4014" />
    </joint>
    <joint name="LWristPitch_joint" type="revolute">
        <origin xyz="0 0 0" rpy="0 -0 0" />
        <axis xyz="0 1 0" />
        <parent link="LWristYaw_link" />
        <child link="LWristPitch_link" />
        <limit effort="0.6" velocity="3.75" lower="-0.988" upper="0.8969" />
    </joint>
    <joint name="TrunkYaw_joint" type="revolute">
        <origin xyz="0 0 0" rpy="0 -0 0" />
        <axis xyz="0 0 1" />
        <parent link="Torso_link" />
        <child link="TrunkYaw_link" />
        <limit effort="28.021" velocity="1.5" lower="-0.7575" upper="0.7575" />
    </joint>
    <joint name="LHipYaw_joint" type="revolute">
        <origin xyz="0.05 0.096 -0.3375" rpy="0 -0 0" />
        <axis xyz="0 0 1" />
        <parent link="TrunkYaw_link" />
        <child link="LHipYaw_link" />
        <limit effort="25.42" velocity="1.045" lower="-0.2618" upper="0.2618" />
    </joint>
    <joint name="LHipRoll_joint" type="revolute">
        <origin xyz="0 0 0" rpy="0 -0 0" />
        <axis xyz="1 0 0" />
        <parent link="LHipYaw_link" />
        <child link="LHipRoll_link" />
        <limit effort="46.6" velocity="2.09" lower="-0.2618" upper="0.5236" />
    </joint>
    <joint name="LHipPitch_joint" type="revolute">
        <origin xyz="0 0 0" rpy="0 -0 0" />
        <axis xyz="0 1 0" />
        <parent link="LHipRoll_link" />
        <child link="LHipPitch_link" />
        <limit effort="46.6" velocity="2.09" lower="-1.6581" upper="0.4014" />
    </joint>
    <joint name="LKneePitch_joint" type="revolute">
        <origin xyz="0 0 -0.322" rpy="0 -0 0" />
        <axis xyz="0 1 0" />
        <parent link="LHipPitch_link" />
        <child link="LKneePitch_link" />
        <limit effort="38.17" velocity="6" lower="-0.0218" upper="1.9722" />
    </joint>
    <joint name="LAnklePitch_joint" type="revolute">
        <origin xyz="0 0 -0.29" rpy="0 -0 0" />
        <axis xyz="0 1 0" />
        <parent link="LKneePitch_link" />
        <child link="LAnklePitch_link" />
        <limit effort="25.76" velocity="2.1" lower="-0.5149" upper="0.7505" />
    </joint>
    <joint name="LAnkleRoll_joint" type="revolute">
        <origin xyz="0 0 0" rpy="0 -0 0" />
        <axis xyz="1 0 0" />
        <parent link="LAnklePitch_link" />
        <child link="LAnkleRoll_link" />
        <limit effort="25.76" velocity="2.1" lower="-0.3491" upper="0.3491" />
    </joint>
    <joint name="RHipYaw_joint" type="revolute">
        <origin xyz="0.05 -0.096 -0.3375" rpy="0 -0 0" />
        <axis xyz="0 0 1" />
        <parent link="TrunkYaw_link" />
        <child link="RHipYaw_link" />
        <limit effort="25.42" velocity="1.045" lower="-0.2618" upper="0.2618" />
    </joint>
    <joint name="RHipRoll_joint" type="revolute">
        <origin xyz="0 0 0" rpy="0 -0 0" />
        <axis xyz="1 0 0" />
        <parent link="RHipYaw_link" />
        <child link="RHipRoll_link" />
        <limit effort="46.6" velocity="2.09" lower="-0.5236" upper="0.2618" />
    </joint>
    <joint name="RHipPitch_joint" type="revolute">
        <origin xyz="0 0 0" rpy="0 -0 0" />
        <axis xyz="0 1 0" />
        <parent link="RHipRoll_link" />
        <child link="RHipPitch_link" />
        <limit effort="46.6" velocity="2.09" lower="-1.6581" upper="0.4014" />
    </joint>
    <joint name="RKneePitch_joint" type="revolute">
        <origin xyz="0 0 -0.322" rpy="0 -0 0" />
        <axis xyz="0 1 0" />
        <parent link="RHipPitch_link" />
        <child link="RKneePitch_link" />
        <limit effort="38.17" velocity="6" lower="-0.0218" upper="1.9722" />
    </joint>
    <joint name="RAnklePitch_joint" type="revolute">
        <origin xyz="0 0 -0.29" rpy="0 -0 0" />
        <axis xyz="0 1 0" />
        <parent link="RKneePitch_link" />
        <child link="RAnklePitch_link" />
        <limit effort="25.76" velocity="2.1" lower="-0.5149" upper="0.7505" />
    </joint>
    <joint name="RAnkleRoll_joint" type="revolute">
        <origin xyz="0 0 0" rpy="0 -0 0" />
        <axis xyz="1 0 0" />
        <parent link="RAnklePitch_link" />
        <child link="RAnkleRoll_link" />
        <limit effort="25.76" velocity="2.1" lower="-0.3491" upper="0.3491" />
    </joint>
    <joint name="RShoulderPitch_joint" type="revolute">
        <origin xyz="0.049862 -0.19 0.073851" rpy="-1.49012e-08 7.45058e-09 0" />
        <axis xyz="-0.417025 0.895055 0.15801" />
        <parent link="Torso_link" />
        <child link="RShoulderPitch_link" />
        <limit effort="19.095" velocity="2.2" lower="-1.4554" upper="2.1399" />
    </joint>
    <joint name="RShoulderYaw_joint" type="revolute">
        <origin xyz="0 0 0" rpy="-2.98023e-08 1.49012e-08 -6.42613e-08" />
        <axis xyz="0.0401398 -0.155542 0.987014" />
        <parent link="RShoulderPitch_link" />
        <child link="RShoulderYaw_link" />
        <limit effort="9.031" velocity="4" lower="-1.0985" upper="0.4025" />
    </joint>
    <joint name="RElbowRoll_joint" type="revolute">
        <origin xyz="0.210824 -1.48548e-08 -0.008631" rpy="6.69388e-09 7.45058e-09 -7.91624e-08" />
        <axis xyz="0.998889 -0.0139984 0.044995" />
        <parent link="RShoulderYaw_link" />
        <child link="RElbowRoll_link" />
        <limit effort="7.404" velocity="3.7" lower="-1.9047" upper="2.2143" />
    </joint>
    <joint name="RElbowYaw_joint" type="revolute">
        <origin xyz="0 0 0" rpy="1.49504e-08 -1.86264e-08 -2.12577e-09" />
        <axis xyz="-0.0449994 0 0.998987" />
        <parent link="RElbowRoll_link" />
        <child link="RElbowYaw_link" />
        <limit effort="6.02" velocity="4" lower="-0.0047" upper="1.5225" />
    </joint>
    <joint name="RWristRoll_joint" type="revolute">
        <origin xyz="0.190404 4.65661e-10 0.008631" rpy="-1.6234e-11 -7.45058e-09 -9.32998e-10" />
        <axis xyz="0.998987 0 0.0449994" />
        <parent link="RElbowYaw_link" />
        <child link="RWristRoll_link" />
        <limit effort="2.177" velocity="1.1" lower="-0.4887" upper="3.6303" />
    </joint>
    <joint name="RWristYaw_joint" type="revolute">
        <origin xyz="0 0 0" rpy="0 -0 0" />
        <axis xyz="-0.0449994 0 0.998987" />
        <parent link="RWristRoll_link" />
        <child link="RWristYaw_link" />
        <limit effort="0.862" velocity="2.26" lower="-0.4014" upper="0.4014" />
    </joint>
    <joint name="RWristPitch_joint" type="revolute">
        <origin xyz="0 0 0" rpy="0 -0 0" />
        <axis xyz="0 1 0" />
        <parent link="RWristYaw_link" />
        <child link="RWristPitch_link" />
        <limit effort="0.6" velocity="3.75" lower="-0.9868" upper="0.8981" />
    </joint>
    <joint name="RArm_effector_fixedjoint" type="fixed">
        <origin xyz="0 0 0" rpy="0 -0 0" />
        <axis xyz="0 0 0" />
        <parent link="RWristPitch_link" />
        <child link="RArm_effector" />
    </joint>
    <joint name="REye_effector_fixedjoint" type="fixed">
        <origin xyz="0 0 0" rpy="0 -0 0" />
        <axis xyz="0 0 0" />
        <parent link="REyePitch_link" />
        <child link="REye_effector" />
    </joint>
    <joint name="RFinger11_joint" type="continuous">
        <origin xyz="0.12385 0.03024 0.00999" rpy="1.69304 -1.5708 3.14159" />
        <axis xyz="0 0 1" />
        <parent link="RWristPitch_link" />
        <child link="RFinger11_link" />
        <mimic offset="0" multiplier="0.988205" joint="RHand_actuator" />
    </joint>
    <joint name="RFinger12_joint" type="continuous">
        <origin xyz="0 0.0230929 4.02331e-06" rpy="0 -0 0" />
        <axis xyz="0 0 1" />
        <parent link="RFinger11_link" />
        <child link="RFinger12_link" />
        <mimic offset="0" multiplier="0.988205" joint="RHand_actuator" />
    </joint>
    <joint name="RFinger13_joint" type="continuous">
        <origin xyz="0 0.0230916 -5.90086e-06" rpy="0 -0 0" />
        <axis xyz="0 0 1" />
        <parent link="RFinger12_link" />
        <child link="RFinger13_link" />
        <mimic offset="0" multiplier="0.988205" joint="RHand_actuator" />
    </joint>
    <joint name="RFinger21_joint" type="continuous">
        <origin xyz="0.12934 0 0.01499" rpy="1.5708 -1.5708 -3.14159" />
        <axis xyz="0 0 1" />
        <parent link="RWristPitch_link" />
        <child link="RFinger21_link" />
        <mimic offset="0" multiplier="0.988205" joint="RHand_actuator" />
    </joint>
    <joint name="RFinger22_joint" type="continuous">
        <origin xyz="0 0.02309 0" rpy="0 -0 0" />
        <axis xyz="0 0 1" />
        <parent link="RFinger21_link" />
        <child link="RFinger22_link" />
        <mimic offset="0" multiplier="0.988205" joint="RHand_actuator" />
    </joint>
    <joint name="RFinger23_joint" type="continuous">
        <origin xyz="0 0.02309 0" rpy="0 -0 0" />
        <axis xyz="0 0 1" />
        <parent link="RFinger22_link" />
        <child link="RFinger23_link" />
        <mimic offset="0" multiplier="0.988205" joint="RHand_actuator" />
    </joint>
    <joint name="RFinger31_joint" type="continuous">
        <origin xyz="0.11215 -0.03024 0.00999" rpy="1.69304 1.5708 3.14159" />
        <axis xyz="0 0 1" />
        <parent link="RWristPitch_link" />
        <child link="RFinger31_link" />
        <mimic offset="0" multiplier="0.988205" joint="RHand_actuator" />
    </joint>
    <joint name="RFinger32_joint" type="continuous">
        <origin xyz="0 -0.0230929 -4.02331e-06" rpy="0 -0 0" />
        <axis xyz="0 0 1" />
        <parent link="RFinger31_link" />
        <child link="RFinger32_link" />
        <mimic offset="0" multiplier="0.988205" joint="RHand_actuator" />
    </joint>
    <joint name="RFinger33_joint" type="continuous">
        <origin xyz="0 -0.0230916 5.90086e-06" rpy="0 -0 0" />
        <axis xyz="0 0 1" />
        <parent link="RFinger32_link" />
        <child link="RFinger33_link" />
        <mimic offset="0" multiplier="0.988205" joint="RHand_actuator" />
    </joint>
    <joint name="RFoot/FSR/CenterFront_sensor_fixedjoint" type="fixed">
        <origin xyz="0.07498 -0.01275 -0.06226" rpy="0 -0 0" />
        <axis xyz="0 0 0" />
        <parent link="RAnkleRoll_link" />
        <child link="RFoot/FSR/CenterFront_sensor" />
    </joint>
    <joint name="RFoot/FSR/CenterRear_sensor_fixedjoint" type="fixed">
        <origin xyz="0.01448 -0.0145 -0.06226" rpy="0 -0 0" />
        <axis xyz="0 0 0" />
        <parent link="RAnkleRoll_link" />
        <child link="RFoot/FSR/CenterRear_sensor" />
    </joint>
    <joint name="RFoot/FSR/HeelLeft_sensor_fixedjoint" type="fixed">
        <origin xyz="-0.04602 0.017 -0.06226" rpy="0 -0 0" />
        <axis xyz="0 0 0" />
        <parent link="RAnkleRoll_link" />
        <child link="RFoot/FSR/HeelLeft_sensor" />
    </joint>
    <joint name="RFoot/FSR/HeelRight_sensor_fixedjoint" type="fixed">
        <origin xyz="-0.04602 -0.017 -0.06226" rpy="0 -0 0" />
        <axis xyz="0 0 0" />
        <parent link="RAnkleRoll_link" />
        <child link="RFoot/FSR/HeelRight_sensor" />
    </joint>
    <joint name="RFoot/FSR/ToeFrontLeft_sensor_fixedjoint" type="fixed">
        <origin xyz="0.17298 0.023 -0.06226" rpy="0 -0 0" />
        <axis xyz="0 0 0" />
        <parent link="RAnkleRoll_link" />
        <child link="RFoot/FSR/ToeFrontLeft_sensor" />
    </joint>
    <joint name="RFoot/FSR/ToeFrontRight_sensor_fixedjoint" type="fixed">
        <origin xyz="0.16098 -0.024 -0.06226" rpy="0 -0 0" />
        <axis xyz="0 0 0" />
        <parent link="RAnkleRoll_link" />
        <child link="RFoot/FSR/ToeFrontRight_sensor" />
    </joint>
    <joint name="RFoot/FSR/ToeRearLeft_sensor_fixedjoint" type="fixed">
        <origin xyz="0.12698 0.0315 -0.06226" rpy="0 -0 0" />
        <axis xyz="0 0 0" />
        <parent link="RAnkleRoll_link" />
        <child link="RFoot/FSR/ToeRearLeft_sensor" />
    </joint>
    <joint name="RFoot/FSR/ToeRearRight_sensor_fixedjoint" type="fixed">
        <origin xyz="0.11898 -0.0335 -0.06226" rpy="0 -0 0" />
        <axis xyz="0 0 0" />
        <parent link="RAnkleRoll_link" />
        <child link="RFoot/FSR/ToeRearRight_sensor" />
    </joint>
    <joint name="RHand_actuator" type="revolute">
        <origin xyz="-0.0579412 -0.0159 -0.00260997" rpy="1.5708 0.0450146 -3.14159" />
        <axis xyz="1 0 0" />
        <parent link="RWristPitch_link" />
        <child link="RHand_actuator_frame" />
        <limit effort="0.649997" velocity="59.8925" lower="0" upper="1" />
    </joint>
    <joint name="RLeg_effector_fixedjoint" type="fixed">
        <origin xyz="0 0 -0.0651" rpy="0 -0 0" />
        <axis xyz="0 0 0" />
        <parent link="RAnkleRoll_link" />
        <child link="RLeg_effector" />
    </joint>
    <joint name="RThumb1_joint" type="continuous">
        <origin xyz="0.0624 0.03131 -0.00574" rpy="0.1638 -1.21665 0" />
        <axis xyz="0 0 1" />
        <parent link="RWristPitch_link" />
        <child link="RThumb1_link" />
        <mimic offset="0" multiplier="1.74533" joint="RHand_actuator" />
    </joint>
    <joint name="RThumb2_joint" type="continuous">
        <origin xyz="-0.000329241 0.0388865 -0.017011" rpy="1.13316 -5.55112e-17 -1.80698" />
        <axis xyz="0 0 1" />
        <parent link="RThumb1_link" />
        <child link="RThumb2_link" />
        <mimic offset="0" multiplier="0.988205" joint="RHand_actuator" />
    </joint>
    <joint name="RThumb3_joint" type="continuous">
        <origin xyz="-0.0187362 -0.0135152 -5.21541e-06" rpy="-5.96047e-08 -1.49012e-08 1.49012e-08" />
        <axis xyz="0 0 1" />
        <parent link="RThumb2_link" />
        <child link="RThumb3_link" />
        <mimic offset="0" multiplier="0.988205" joint="RHand_actuator" />
    </joint>
    <joint name="Trunk_effector_fixedjoint" type="fixed">
        <origin xyz="0 0 0" rpy="0 -0 0" />
        <axis xyz="0 0 0" />
        <parent link="TrunkYaw_link" />
        <child link="Trunk_effector" />
    </joint>
    <joint name="base_link_fixedjoint" type="fixed">
        <origin xyz="0 0 0" rpy="0 -0 0" />
        <axis xyz="0 0 0" />
        <parent link="base_link" />
        <child link="Torso_link" />
    </joint>
</robot>
