<?xml version="1.0" ?>
<!-- =================================================================================== -->
<!-- |    This document was autogenerated by xacro from romeorobot.xacro               | -->
<!-- |    EDITING THIS FILE BY HAND IS NOT RECOMMENDED                                 | -->
<!-- =================================================================================== -->
<!-- ***************************************************************** 
 ****** File automatically generated by generate_urdf.py script ****** 
 ********************************************************************* -->
<robot name="romeoH37V1" xmlns:xacro="http://www.ros.org/wiki/xacro">
  <joint name="NeckYaw" type="revolute">
    <parent link="torso"/>
    <child link="NeckYawLink"/>
    <origin rpy="0 0 0" xyz="0 0 0.0835"/>
    <axis xyz="0 0 1.0"/>
    <limit effort="3.662" lower="-1.5708" upper="1.5708" velocity="4.0"/>
  </joint>
  <link name="NeckYawLink">
    <inertial>
      <mass value="0.51016"/>
      <inertia ixx="0.00122159" ixy="-8.014e-08" ixz="1.145e-08" iyy="0.00124608" iyz="-1.84095e-06" izz="0.000187965"/>
      <origin rpy="0 0 0" xyz="0 0 -0.03074"/>
    </inertial>
  </link>
  <joint name="NeckPitch" type="revolute">
    <parent link="NeckYawLink"/>
    <child link="NeckPitchLink"/>
    <origin rpy="0 0 0" xyz="0 0 0"/>
    <axis xyz="0 1.0 0"/>
    <limit effort="2.978" lower="-0.349066" upper="0.698132" velocity="2.2"/>
  </joint>
  <link name="NeckPitchLink">
    <inertial>
      <mass value="0.23875"/>
      <inertia ixx="0.000866022" ixy="-1.57263e-06" ixz="6.13825e-05" iyy="0.000818287" iyz="9.69515e-06" izz="0.000238919"/>
      <origin rpy="0 0 0" xyz="-0.00472 0 0.04432"/>
    </inertial>
    <visual>
      <geometry>
        <mesh filename="package://romeo_description/meshes/V1/visual/NeckPitch.dae" scale="1 1 1"/>
      </geometry>
    </visual>
    <collision>
      <geometry>
        <mesh filename="package://romeo_description/meshes/V1/collision/NeckPitch.dae" scale="1 1 1"/>
      </geometry>
    </collision>
  </link>
  <joint name="HeadPitch" type="revolute">
    <parent link="NeckPitchLink"/>
    <child link="HeadPitchLink"/>
    <origin rpy="0 0 0" xyz="0 0 0.09511"/>
    <axis xyz="0 1.0 0"/>
    <limit effort="2.57" lower="-0.349066" upper="0.279253" velocity="1.9"/>
  </joint>
  <link name="HeadPitchLink">
    <inertial>
      <mass value="0.13981"/>
      <inertia ixx="3.89601e-05" ixy="-3.814e-08" ixz="-2.29622e-06" iyy="7.25465e-05" iyz="-6.46e-09" izz="5.3765e-05"/>
      <origin rpy="0 0 0" xyz="0.00137 0 -0.00641"/>
    </inertial>
  </link>
  <joint name="HeadRoll" type="revolute">
    <parent link="HeadPitchLink"/>
    <child link="HeadRollLink"/>
    <origin rpy="0 0 0" xyz="0 0 0"/>
    <axis xyz="1.0 0 0"/>
    <limit effort="0.9" lower="-0.349066" upper="0.349066" velocity="1.5"/>
  </joint>
  <link name="HeadRollLink">
    <inertial>
      <mass value="1.41282"/>
      <inertia ixx="0.0149087" ixy="-5.14209e-05" ixz="-0.000684893" iyy="0.0173189" iyz="-0.000191527" izz="0.00735475"/>
      <origin rpy="0 0 0" xyz="0.01617 0 0.00757"/>
    </inertial>
    <visual>
      <geometry>
        <mesh filename="package://romeo_description/meshes/V1/visual/HeadRoll.dae" scale="1 1 1"/>
      </geometry>
    </visual>
    <collision>
      <geometry>
        <mesh filename="package://romeo_description/meshes/V1/collision/HeadRoll.dae" scale="1 1 1"/>
      </geometry>
    </collision>
  </link>
  
  <link name="torso">
    <inertial>
      <mass value="9.9216"/>
      <inertia ixx="0.129332" ixy="-0.000359651" ixz="0.00283888" iyy="0.126831" iyz="-0.00200843" izz="0.110627"/>
      <origin rpy="0 0 0" xyz="0.0023 0 -0.04854"/>
    </inertial>
    <visual>
      <geometry>
        <mesh filename="package://romeo_description/meshes/V1/visual/Torso.dae" scale="1 1 1"/>
      </geometry>
    </visual>
    <collision>
      <geometry>
        <mesh filename="package://romeo_description/meshes/V1/collision/Torso.dae" scale="1 1 1"/>
      </geometry>
    </collision>
  </link>
 <!-- <joint name="TrunkYaw" type="revolute">
    <parent link="torso"/>
    <origin rpy="0 0 0" xyz="0 0 -0.2"/>
    <axis xyz="0 0 1.0"/>
    <limit effort="80.902" lower="-0.785398" upper="0.785398" velocity="1.5"/>
  </joint>-->
  <joint name="LShoulderPitch" type="revolute">
    <parent link="torso"/>
    <child link="LShoulderPitchLink"/>
    <origin rpy="-0.158879 -0.0725189 -0.424682" xyz="0.005 0.19 0"/>
    <axis xyz="0 1.0 0"/>
    <limit effort="19.095" lower="-1.44478" upper="2.22041" velocity="2.2"/>
  </joint>
  <link name="LShoulderPitchLink">
    <inertial>
      <mass value="0.69402"/>
      <inertia ixx="0.00201004" ixy="2.37595e-06" ixz="-2.16793e-06" iyy="0.000570626" iyz="8.27832e-06" izz="0.00194068"/>
      <origin rpy="0 0 0" xyz="0.00149 -0.03299 0.00018"/>
    </inertial>
  </link>
  <joint name="LShoulderYaw" type="revolute">
    <parent link="LShoulderPitchLink"/>
    <child link="LShoulderYawLink"/>
    <origin rpy="0 0 0.430457" xyz="0 0 0"/>
    <axis xyz="0 0 1.0"/>
    <limit effort="9.031" lower="-0.430472" upper="1.14032" velocity="4.0"/>
  </joint>
  <link name="LShoulderYawLink">
    <inertial>
      <mass value="0.57151"/>
      <inertia ixx="0.000742818" ixy="-0.000617675" ixz="-7.28438e-05" iyy="0.00650202" iyz="-1.25157e-05" izz="0.00664434"/>
      <origin rpy="0 0 0" xyz="0.09367 0.01373 0.00103"/>
    </inertial>
    <visual>
      <geometry>
        <mesh filename="package://romeo_description/meshes/V1/visual/LShoulderYaw.dae" scale="1 1 1"/>
      </geometry>
    </visual>
    <collision>
      <geometry>
        <mesh filename="package://romeo_description/meshes/V1/collision/LShoulderYaw.dae" scale="1 1 1"/>
      </geometry>
    </collision>
  </link>
  <joint name="LElbowRoll" type="revolute">
    <parent link="LShoulderYawLink"/>
    <child link="LElbowRollLink"/>
    <origin rpy="0.17452 0 0" xyz="0.205 0 0"/>
    <axis xyz="1.0 0 0"/>
    <limit effort="7.404" lower="-2.0944" upper="2.0944" velocity="3.7"/>
  </joint>
  <link name="LElbowRollLink">
    <inertial>
      <mass value="0.39848"/>
      <inertia ixx="0.000179003" ixy="-2.25555e-06" ixz="1.376e-08" iyy="0.000804322" iyz="8.007e-08" izz="0.00077956"/>
      <origin rpy="0 0 0" xyz="-0.02231 -0.0024 0"/>
    </inertial>
  </link>
  <joint name="LElbowYaw" type="revolute">
    <parent link="LElbowRollLink"/>
    <child link="LElbowYawLink"/>
    <origin rpy="0 0 0" xyz="0 0 0"/>
    <axis xyz="0 0 1.0"/>
    <limit effort="6.02" lower="-1.5708" upper="0" velocity="4.0"/>
  </joint>
  <link name="LElbowYawLink">
    <inertial>
      <mass value="0.31265"/>
      <inertia ixx="0.000375096" ixy="-0.000225283" ixz="2.58073e-06" iyy="0.00209728" iyz="2.74613e-06" izz="0.00211065"/>
      <origin rpy="0 0 0" xyz="0.06738 0.01043 -0.00031"/>
    </inertial>
    <visual>
      <geometry>
        <mesh filename="package://romeo_description/meshes/V1/visual/LElbowYaw.dae" scale="1 1 1"/>
      </geometry>
    </visual>
    <collision>
      <geometry>
        <mesh filename="package://romeo_description/meshes/V1/collision/LElbowYaw.dae" scale="1 1 1"/>
      </geometry>
    </collision>
  </link>
  <joint name="LWristRoll" type="revolute">
    <parent link="LElbowYawLink"/>
    <child link="LWristRollLink"/>
    <origin rpy="0 0 0" xyz="0.1823 0 0"/>
    <axis xyz="1.0 0 0"/>
    <limit effort="2.177" lower="-3.66519" upper="0.523599" velocity="1.1"/>
  </joint>
  <link name="LWristRollLink">
    <inertial>
      <mass value="0.17563"/>
      <inertia ixx="6.72145e-05" ixy="-6.373e-07" ixz="-1.35809e-05" iyy="0.000851196" iyz="-2.443e-08" izz="0.000840348"/>
      <origin rpy="0 0 0" xyz="-0.0593 -5e-05 -0.00069"/>
    </inertial>
    <visual>
      <geometry>
        <mesh filename="package://romeo_description/meshes/V1/visual/LWristRoll.dae" scale="1 1 1"/>
      </geometry>
    </visual>
    <collision>
      <geometry>
        <mesh filename="package://romeo_description/meshes/V1/collision/LWristRoll.dae" scale="1 1 1"/>
      </geometry>
    </collision>
  </link>
  <joint name="LWristYaw" type="revolute">
    <parent link="LWristRollLink"/>
    <child link="LWristYawLink"/>
    <origin rpy="0 0 0" xyz="0 0 0"/>
    <axis xyz="0 0 1.0"/>
    <limit effort="0.862" lower="-0.436332" upper="0.436332" velocity="2.26"/>
  </joint>
  <link name="LWristYawLink">
    <inertial>
      <mass value="0.07595"/>
      <inertia ixx="1.45402e-05" ixy="-4.157e-08" ixz="7.674e-08" iyy="3.91907e-05" iyz="3.08e-09" izz="3.81787e-05"/>
      <origin rpy="0 0 0" xyz="-0.00746 -0.00016 -0.00022"/>
    </inertial>
    <visual>
      <geometry>
        <mesh filename="package://romeo_description/meshes/V1/visual/LWristYaw.dae" scale="1 1 1"/>
      </geometry>
    </visual>
    <collision>
      <geometry>
        <mesh filename="package://romeo_description/meshes/V1/collision/LWristYaw.dae" scale="1 1 1"/>
      </geometry>
    </collision>
  </link>
  <joint name="LWristPitch" type="revolute">
    <parent link="LWristYawLink"/>
    <child link="l_wrist"/>
    <origin rpy="0 0 0" xyz="0 0 0"/>
    <axis xyz="0 1.0 0"/>
    <limit effort="0.6" lower="-0.977384" upper="0.977384" velocity="3.75"/>
  </joint>
  <link name="l_wrist">
    <inertial>
      <mass value="0.16569"/>
      <inertia ixx="0.000112529" ixy="4.72583e-05" ixz="1.70404e-05" iyy="0.00107982" iyz="-1.54761e-05" izz="0.00115367"/>
      <origin rpy="0 0 0" xyz="0.06987 -0.00381 -0.00165"/>
    </inertial>
    <visual>
      <geometry>
        <mesh filename="package://romeo_description/meshes/V1/visual/LWristPitch.dae" scale="1 1 1"/>
      </geometry>
    </visual>
    <collision>
      <geometry>
        <mesh filename="package://romeo_description/meshes/V1/collision/LWristPitch.dae" scale="1 1 1"/>
      </geometry>
    </collision>
  </link>
  <joint name="RShoulderPitch" type="revolute">
    <parent link="torso"/>
    <child link="RShoulderPitchLink"/>
    <origin rpy="0.158879 -0.0725189 0.424682" xyz="0.005 -0.19 0"/>
    <axis xyz="0 1.0 0"/>
    <limit effort="19.095" lower="-1.44478" upper="2.22041" velocity="2.2"/>
  </joint>
  <link name="RShoulderPitchLink">
    <inertial>
      <mass value="0.69402"/>
      <inertia ixx="0.00201004" ixy="-2.37595e-06" ixz="2.16793e-06" iyy="0.000570626" iyz="8.27832e-06" izz="0.00194068"/>
      <origin rpy="0 0 0" xyz="0.00149 0.03299 0.00018"/>
    </inertial>
  </link>
  <joint name="RShoulderYaw" type="revolute">
    <parent link="RShoulderPitchLink"/>
    <child link="RShoulderYawLink"/>
    <origin rpy="0 0 -0.430457" xyz="0 0 0"/>
    <axis xyz="0 0 1.0"/>
    <limit effort="9.031" lower="-1.14032" upper="0.430472" velocity="4.0"/>
  </joint>
  <link name="RShoulderYawLink">
    <inertial>
      <mass value="0.57151"/>
      <inertia ixx="0.000742356" ixy="0.000617202" ixz="5.98521e-06" iyy="0.00649989" iyz="-1.07417e-06" izz="0.000664209"/>
      <origin rpy="0 0 0" xyz="0.09367 -0.01373 0.00103"/>
    </inertial>
    <visual>
      <geometry>
        <mesh filename="package://romeo_description/meshes/V1/visual/RShoulderYaw.dae" scale="1 1 1"/>
      </geometry>
    </visual>
    <collision>
      <geometry>
        <mesh filename="package://romeo_description/meshes/V1/collision/RShoulderYaw.dae" scale="1 1 1"/>
      </geometry>
    </collision>
  </link>
  <joint name="RElbowRoll" type="revolute">
    <parent link="RShoulderYawLink"/>
    <child link="RElbowRollLink"/>
    <origin rpy="-0.17452 0 0" xyz="0.205 0 0"/>
    <axis xyz="1.0 0 0"/>
    <limit effort="7.404" lower="-2.0944" upper="2.0944" velocity="3.7"/>
  </joint>
  <link name="RElbowRollLink">
    <inertial>
      <mass value="0.39848"/>
      <inertia ixx="0.000179003" ixy="-2.25555e-06" ixz="1.376e-08" iyy="0.000804322" iyz="8.007e-08" izz="0.00077956"/>
      <origin rpy="0 0 0" xyz="-0.02231 0.0024 0"/>
    </inertial>
  </link>
  <joint name="RElbowYaw" type="revolute">
    <parent link="RElbowRollLink"/>
    <child link="RElbowYawLink"/>
    <origin rpy="0 0 0" xyz="0 0 0"/>
    <axis xyz="0 0 1.0"/>
    <limit effort="6.02" lower="0" upper="1.5708" velocity="4.0"/>
  </joint>
  <link name="RElbowYawLink">
    <inertial>
      <mass value="0.31265"/>
      <inertia ixx="0.000366728" ixy="0.000185631" ixz="-5.37905e-07" iyy="0.00211104" iyz="3.1932e-07" izz="0.000211493"/>
      <origin rpy="0 0 0" xyz="0.06738 -0.01043 -0.00031"/>
    </inertial>
    <visual>
      <geometry>
        <mesh filename="package://romeo_description/meshes/V1/visual/RElbowYaw.dae" scale="1 1 1"/>
      </geometry>
    </visual>
    <collision>
      <geometry>
        <mesh filename="package://romeo_description/meshes/V1/collision/RElbowYaw.dae" scale="1 1 1"/>
      </geometry>
    </collision>
  </link>
  <joint name="RWristRoll" type="revolute">
    <parent link="RElbowYawLink"/>
    <child link="RWristRollLink"/>
    <origin rpy="0 0 0" xyz="0.1823 0 0"/>
    <axis xyz="1.0 0 0"/>
    <limit effort="2.177" lower="-0.523599" upper="3.66519" velocity="1.1"/>
  </joint>
  <link name="RWristRollLink">
    <inertial>
      <mass value="0.17563"/>
      <inertia ixx="6.72145e-05" ixy="-6.373e-07" ixz="-1.35809e-05" iyy="0.000851196" iyz="-2.443e-08" izz="0.000840348"/>
      <origin rpy="0 0 0" xyz="-0.0593 5e-05 -0.00069"/>
    </inertial>
    <visual>
      <geometry>
        <mesh filename="package://romeo_description/meshes/V1/visual/RWristRoll.dae" scale="1 1 1"/>
      </geometry>
    </visual>
    <collision>
      <geometry>
        <mesh filename="package://romeo_description/meshes/V1/collision/RWristRoll.dae" scale="1 1 1"/>
      </geometry>
    </collision>
  </link>
  <joint name="RWristYaw" type="revolute">
    <parent link="RWristRollLink"/>
    <child link="RWristYawLink"/>
    <origin rpy="0 0 0" xyz="0 0 0"/>
    <axis xyz="0 0 1.0"/>
    <limit effort="0.862" lower="-0.436332" upper="0.436332" velocity="2.26"/>
  </joint>
  <link name="RWristYawLink">
    <inertial>
      <mass value="0.07595"/>
      <inertia ixx="1.45402e-05" ixy="-4.157e-08" ixz="7.674e-08" iyy="3.91907e-05" iyz="3.08e-09" izz="3.81787e-05"/>
      <origin rpy="0 0 0" xyz="-0.00746 0.00016 -0.00022"/>
    </inertial>
    <visual>
      <geometry>
        <mesh filename="package://romeo_description/meshes/V1/visual/RWristYaw.dae" scale="1 1 1"/>
      </geometry>
    </visual>
    <collision>
      <geometry>
        <mesh filename="package://romeo_description/meshes/V1/collision/RWristYaw.dae" scale="1 1 1"/>
      </geometry>
    </collision>
  </link>
  <joint name="RWristPitch" type="revolute">
    <parent link="RWristYawLink"/>
    <child link="r_wrist"/>
    <origin rpy="0 0 0" xyz="0 0 0"/>
    <axis xyz="0 1.0 0"/>
    <limit effort="0.6" lower="-0.977384" upper="0.977384" velocity="3.75"/>
  </joint>
  <link name="r_wrist">
    <inertial>
      <mass value="0.16569"/>
      <inertia ixx="0.000112529" ixy="0" ixz="0" iyy="0.00107982" iyz="0" izz="0.00115367"/>
      <origin rpy="0 0 0" xyz="0.06987 0.00381 -0.00165"/>
    </inertial>
    <visual>
      <geometry>
        <mesh filename="package://romeo_description/meshes/V1/visual/RWristPitch.dae" scale="1 1 1"/>
      </geometry>
    </visual>
    <collision>
      <geometry>
        <mesh filename="package://romeo_description/meshes/V1/collision/RWristPitch.dae" scale="1 1 1"/>
      </geometry>
    </collision>
  </link>
  


  
</robot>

