<robot name="RomeoH37">

<link name="base_link"/>
  <joint name="base_joint" type="floating">
    <parent link="base_link"/>
    <child link="Torso_link"/>
    <origin rpy="0 0 0" xyz="0 0 0"/>
  </joint> 

    <link name="Torso_link">
        <inertial>
            <mass value="5.85463" />
            <origin xyz="0.01512 0 0.06743" rpy="0 -0 0" />
            <inertia ixx="0.0587116" ixy="-3.02711e-06" ixz="0.0101426" iyy="0.0326812" iyz="-0.000132541" izz="0.0637705" />
        </inertial>
        <visual>
            <origin xyz="0 0 0" rpy="0 -0 0" />
            <geometry>
                <mesh filename="package://romeo/meshes/Torso.mesh" scale="1 1 1" />
            </geometry>
            <material name="LightGrey">
                <texture />
                <color rgba="0.9 0.9 0.9 1" />
            </material>
        </visual>
    </link>
    <link name="NeckYaw_link">
        <inertial>
            <mass value="0.377845" />
            <origin xyz="-0.00635646 0 -0.030002" rpy="0 -0 0" />
            <inertia ixx="0.000279258" ixy="-3.10908e-07" ixz="-1.49231e-05" iyy="0.000260188" iyz="-8.07538e-07" izz="8.41479e-05" />
        </inertial>
    </link>
    <link name="NeckPitch_link">
        <inertial>
            <mass value="0.345282" />
            <origin xyz="0.00372 0 0.04811" rpy="0 -0 0" />
            <inertia ixx="0.000476367" ixy="-1.93678e-06" ixz="0.000128915" iyy="0.000443007" iyz="5.81865e-05" izz="0.000304636" />
        </inertial>
        <visual>
            <origin xyz="0 0 0" rpy="0 -0 0" />
            <geometry>
                <mesh filename="package://romeo/meshes/NeckPitch.mesh" scale="1 1 1" />
            </geometry>
            <material name="LightGrey">
                <texture />
                <color rgba="0.9 0.9 0.9 1" />
            </material>
        </visual>
    </link>
    <link name="HeadPitch_link">
        <inertial>
            <mass value="0.158407" />
            <origin xyz="0.0014 0 -0.00462" rpy="0 -0 0" />
            <inertia ixx="2.57346e-05" ixy="1.51196e-07" ixz="-1.52238e-05" iyy="7.43865e-05" iyz="-4.91562e-09" izz="6.6769e-05" />
        </inertial>
    </link>
    <link name="HeadRoll_link">
        <inertial>
            <mass value="2.07047" />
            <origin xyz="0.01263 0 0.07498" rpy="0 -0 0" />
            <inertia ixx="0.00933153" ixy="-3.87986e-05" ixz="0.002764" iyy="0.0110877" iyz="0.000300351" izz="0.00918888" />
        </inertial>
        <visual>
            <origin xyz="0 0 0" rpy="0 -0 0" />
            <geometry>
                <mesh filename="package://romeo/meshes/HeadRoll.mesh" scale="1 1 1" />
            </geometry>
            <material name="LightGrey">
                <texture />
                <color rgba="0.9 0.9 0.9 1" />
            </material>
        </visual>
    </link>
    <link name="LEyeYaw_link">
        <inertial>
            <mass value="0.01" />
            <origin xyz="0 0 0" rpy="0 -0 0" />
            <inertia ixx="0" ixy="0" ixz="0" iyy="0" iyz="0" izz="0" />
        </inertial>
    </link>
    <link name="LEyePitch_link">
        <inertial>
            <mass value="0.01" />
            <origin xyz="0 0 0" rpy="0 -0 0" />
            <inertia ixx="0" ixy="0" ixz="0" iyy="0" iyz="0" izz="0" />
        </inertial>
        <visual>
            <origin xyz="0 0 0" rpy="0 -0 0" />
            <geometry>
                <mesh filename="package://romeo/meshes/LEye.mesh" scale="1 1 1" />
            </geometry>
            <material name="LightGrey">
                <texture />
                <color rgba="0.9 0.9 0.9 1" />
            </material>
        </visual>
    </link>
    <link name="REyeYaw_link">
        <inertial>
            <mass value="0.01" />
            <origin xyz="0 0 0" rpy="0 -0 0" />
            <inertia ixx="0" ixy="0" ixz="0" iyy="0" iyz="0" izz="0" />
        </inertial>
    </link>
    <link name="REyePitch_link">
        <inertial>
            <mass value="0.01" />
            <origin xyz="0 0 0" rpy="0 -0 0" />
            <inertia ixx="0" ixy="0" ixz="0" iyy="0" iyz="0" izz="0" />
        </inertial>
        <visual>
            <origin xyz="0 0 0" rpy="0 -0 0" />
            <geometry>
                <mesh filename="package://romeo/meshes/REye.mesh" scale="1 1 1" />
            </geometry>
            <material name="LightGrey">
                <texture />
                <color rgba="0.9 0.9 0.9 1" />
            </material>
        </visual>
    </link>
    <link name="LShoulderPitch_link">
        <inertial>
            <mass value="0.541429" />
            <origin xyz="-0.0112798 -0.0260712 0.00468882" rpy="0 -0 0" />
            <inertia ixx="0.00033428" ixy="-9.92972e-05" ixz="9.98217e-06" iyy="0.000188073" iyz="2.14339e-05" izz="0.000360929" />
        </inertial>
    </link>
    <link name="LShoulderYaw_link">
        <inertial>
            <mass value="0.861545" />
            <origin xyz="0.0965281 0.00465308 0.00168775" rpy="0 -0 0" />
            <inertia ixx="0.00118557" ixy="0.000596133" ixz="0.0011173" iyy="0.00312162" iyz="-2.05919e-05" izz="0.00289955" />
        </inertial>
        <visual>
            <origin xyz="0 0 0" rpy="0 -0 0" />
            <geometry>
                <mesh filename="package://romeo/meshes/LShoulderYaw.mesh" scale="1 1 1" />
            </geometry>
            <material name="LightGrey">
                <texture />
                <color rgba="0.9 0.9 0.9 1" />
            </material>
        </visual>
    </link>
    <link name="LElbowRoll_link">
        <inertial>
            <mass value="0.600439" />
            <origin xyz="-0.0348859 -0.0011589 -0.00148134" rpy="0 -0 0" />
            <inertia ixx="0.000207598" ixy="1.2053e-05" ixz="-1.86312e-05" iyy="0.000507683" iyz="1.56171e-06" izz="0.000456309" />
        </inertial>
    </link>
    <link name="LElbowYaw_link">
        <inertial>
            <mass value="0.460203" />
            <origin xyz="0.068523 0.0097 0.00458766" rpy="0 -0 0" />
            <inertia ixx="0.000503576" ixy="0.000585803" ixz="3.19975e-05" iyy="0.00127777" iyz="3.67296e-05" izz="0.00122813" />
        </inertial>
        <visual>
            <origin xyz="0 0 0" rpy="0 -0 0" />
            <geometry>
                <mesh filename="package://romeo/meshes/LElbowYaw.mesh" scale="1 1 1" />
            </geometry>
            <material name="LightGrey">
                <texture />
                <color rgba="0.9 0.9 0.9 1" />
            </material>
        </visual>
    </link>
    <link name="LWristRoll_link">
        <inertial>
            <mass value="0.218316" />
            <origin xyz="-0.0592449 6e-05 -0.00144745" rpy="0 -0 0" />
            <inertia ixx="0.000100812" ixy="-1.81881e-06" ixz="-4.56681e-05" iyy="0.000384336" iyz="-1.11019e-07" izz="0.000366084" />
        </inertial>
        <visual>
            <origin xyz="0 0 0" rpy="0 -0 0" />
            <geometry>
                <mesh filename="package://romeo/meshes/LWristRoll.mesh" scale="1 1 1" />
            </geometry>
            <material name="LightGrey">
                <texture />
                <color rgba="0.9 0.9 0.9 1" />
            </material>
        </visual>
    </link>
    <link name="LWristYaw_link">
        <inertial>
            <mass value="0.0758774" />
            <origin xyz="-0.00657144 0.00017 -0.000115829" rpy="0 -0 0" />
            <inertia ixx="1.55687e-05" ixy="-5.1829e-08" ixz="-8.72923e-07" iyy="3.52487e-05" iyz="1.94513e-08" izz="3.4791e-05" />
        </inertial>
        <visual>
            <origin xyz="0 0 0" rpy="0 -0 0" />
            <geometry>
                <mesh filename="package://romeo/meshes/LWristYaw.mesh" scale="1 1 1" />
            </geometry>
            <material name="LightGrey">
                <texture />
                <color rgba="0.9 0.9 0.9 1" />
            </material>
        </visual>
    </link>
    <link name="LWristPitch_link">
        <inertial>
            <mass value="0.442191" />
            <origin xyz="0.07358 -0.00628 -0.00098" rpy="0 -0 0" />
            <inertia ixx="0.000404603" ixy="-0.000404247" ixz="1.89685e-05" iyy="0.000829354" iyz="7.81042e-05" izz="0.00102014" />
        </inertial>
        <visual>
            <origin xyz="0 0 0" rpy="0 -0 0" />
            <geometry>
                <mesh filename="package://romeo/meshes/LWristPitch.mesh" scale="1 1 1" />
            </geometry>
            <material name="LightGrey">
                <texture />
                <color rgba="0.9 0.9 0.9 1" />
            </material>
        </visual>
    </link>
    
    <link name="RShoulderPitch_link">
        <inertial>
            <mass value="0.541429" />
            <origin xyz="-0.0112798 0.0260712 0.00468882" rpy="0 -0 0" />
            <inertia ixx="0.00032868" ixy="0.000102539" ixz="1.9336e-05" iyy="0.000199958" iyz="-3.81835e-05" izz="0.000354645" />
        </inertial>
    </link>
    <link name="RShoulderYaw_link">
        <inertial>
            <mass value="0.861545" />
            <origin xyz="0.0965281 -0.00465308 0.00168775" rpy="0 -0 0" />
            <inertia ixx="0.00118857" ixy="-0.00036285" ixz="0.001154" iyy="0.00311916" iyz="1.86519e-05" izz="0.002899" />
        </inertial>
        <visual>
            <origin xyz="0 0 0" rpy="0 -0 0" />
            <geometry>
                <mesh filename="package://romeo/meshes/RShoulderYaw.mesh" scale="1 1 1" />
            </geometry>
            <material name="LightGrey">
                <texture />
                <color rgba="0.9 0.9 0.9 1" />
            </material>
        </visual>
    </link>
    <link name="RElbowRoll_link">
        <inertial>
            <mass value="0.600439" />
            <origin xyz="-0.0348859 0.0011589 -0.00148134" rpy="0 -0 0" />
            <inertia ixx="0.000207722" ixy="-7.62167e-06" ixz="-1.85932e-05" iyy="0.000507556" iyz="9.54211e-07" izz="0.000456313" />
        </inertial>
    </link>
    <link name="RElbowYaw_link">
        <inertial>
            <mass value="0.460203" />
            <origin xyz="0.068523 -0.0097 0.00458766" rpy="0 -0 0" />
            <inertia ixx="0.000503576" ixy="-2.59661e-05" ixz="3.19975e-05" iyy="0.00127777" iyz="-4.2287e-06" izz="0.00122813" />
        </inertial>
        <visual>
            <origin xyz="0 0 0" rpy="0 -0 0" />
            <geometry>
                <mesh filename="package://romeo/meshes/RElbowYaw.mesh" scale="1 1 1" />
            </geometry>
            <material name="LightGrey">
                <texture />
                <color rgba="0.9 0.9 0.9 1" />
            </material>
        </visual>
    </link>
    <link name="RWristRoll_link">
        <inertial>
            <mass value="0.218316" />
            <origin xyz="-0.0592449 -6e-05 -0.00144745" rpy="0 -0 0" />
            <inertia ixx="0.000100812" ixy="-2.66721e-07" ixz="-4.56681e-05" iyy="0.000384336" iyz="-7.30984e-08" izz="0.000366084" />
        </inertial>
        <visual>
            <origin xyz="0 0 0" rpy="0 -0 0" />
            <geometry>
                <mesh filename="package://romeo/meshes/RWristRoll.mesh" scale="1 1 1" />
            </geometry>
            <material name="LightGrey">
                <texture />
                <color rgba="0.9 0.9 0.9 1" />
            </material>
        </visual>
    </link>
    <link name="RWristYaw_link">
        <inertial>
            <mass value="0.0758774" />
            <origin xyz="-0.00657144 -0.00017 -0.000115829" rpy="0 -0 0" />
            <inertia ixx="1.55687e-05" ixy="1.17703e-07" ixz="-8.72923e-07" iyy="3.52487e-05" iyz="2.24395e-08" izz="3.4791e-05" />
        </inertial>
        <visual>
            <origin xyz="0 0 0" rpy="0 -0 0" />
            <geometry>
                <mesh filename="package://romeo/meshes/RWristYaw.mesh" scale="1 1 1" />
            </geometry>
            <material name="LightGrey">
                <texture />
                <color rgba="0.9 0.9 0.9 1" />
            </material>
        </visual>
    </link>
    <link name="RWristPitch_link">
        <inertial>
            <mass value="0.442191" />
            <origin xyz="0.07358 0.00628 -0.00098" rpy="0 -0 0" />
            <inertia ixx="0.000404603" ixy="4.4107e-06" ixz="1.89685e-05" iyy="0.000829354" iyz="7.26613e-05" izz="0.00102014" />
        </inertial>
        <visual>
            <origin xyz="0 0 0" rpy="0 -0 0" />
            <geometry>
                <mesh filename="package://romeo/meshes/RWristPitch.mesh" scale="1 1 1" />
            </geometry>
            <material name="LightGrey">
                <texture />
                <color rgba="0.9 0.9 0.9 1" />
            </material>
        </visual>
    </link>
    <link name="TrunkYaw_link">
        <inertial>
            <mass value="4.4142" />
            <origin xyz="0.02825 0 -0.16653" rpy="0 -0 0" />
            <inertia ixx="0.0487058" ixy="6.27009e-05" ixz="-0.0496477" iyy="0.0449798" iyz="-2.92721e-05" izz="0.0182883" />
        </inertial>
        <visual>
            <origin xyz="0 0 0" rpy="0 -0 0" />
            <geometry>
                <mesh filename="file:///usr/local/share/alrobotmodel/meshes/romeo/TrunkYaw.mesh" scale="1 1 1" />
            </geometry>
            <material name="LightGrey">
                <texture />
                <color rgba="0.9 0.9 0.9 1" />
            </material>
        </visual>
    </link>
   
    <joint name="TrunkYaw_joint" type="revolute">
        <origin xyz="0 0 0" rpy="0 -0 0" />
        <axis xyz="0 0 1" />
        <parent link="Torso_link" />
        <child link="TrunkYaw_link" />
        <limit effort="28.021" velocity="1.5" lower="-0.7575" upper="0.7575" />
    </joint>
    <joint name="NeckYaw_joint" type="revolute">
        <origin xyz="0.0548 0 0.1675" rpy="0 -2.98023e-08 0" />
        <axis xyz="0.173651 0 0.984807" />
        <parent link="Torso_link" />
        <child link="NeckYaw_link" />
        <limit effort="7.324" velocity="4" lower="-2.0595" upper="2.0595" />
    </joint>
    <joint name="NeckPitch_joint" type="revolute">
        <origin xyz="0 0 0" rpy="0 -2.98023e-08 0" />
        <axis xyz="0 1 0" />
        <parent link="NeckYaw_link" />
        <child link="NeckPitch_link" />
        <limit effort="5.956" velocity="2.2" lower="-0.3142" upper="0.6632" />
    </joint>
    <joint name="HeadPitch_joint" type="revolute">
        <origin xyz="0 0 0.0951" rpy="0 -0 0" />
        <axis xyz="0 1 0" />
        <parent link="NeckPitch_link" />
        <child link="HeadPitch_link" />
        <limit effort="2.57" velocity="1.9" lower="-0.2571" upper="0.2971" />
    </joint>
    <joint name="HeadRoll_joint" type="revolute">
        <origin xyz="0 0 0" rpy="0 -0 0" />
        <axis xyz="1 0 0" />
        <parent link="HeadPitch_link" />
        <child link="HeadRoll_link" />
        <limit effort="3.748" velocity="1.5" lower="-0.4887" upper="0.4887" />
    </joint>
    <joint name="LEyeYaw_joint" type="revolute">
        <origin xyz="0.08948 0.03192 0.05425" rpy="0 -0 0" />
        <axis xyz="0 0 1" />
        <parent link="HeadRoll_link" />
        <child link="LEyeYaw_link" />
        <limit effort="0.01752" velocity="293.215" lower="-0.523599" upper="0.523599" />
    </joint>
    <joint name="LEyePitch_joint" type="revolute">
        <origin xyz="0 0 0" rpy="0 -0 0" />
        <axis xyz="0 1 0" />
        <parent link="LEyeYaw_link" />
        <child link="LEyePitch_link" />
        <limit effort="0.01752" velocity="293.215" lower="-0.349066" upper="0.349066" />
    </joint>
    <joint name="REyeYaw_joint" type="revolute">
        <origin xyz="0.08948 -0.03192 0.05425" rpy="0 -0 0" />
        <axis xyz="0 0 1" />
        <parent link="HeadRoll_link" />
        <child link="REyeYaw_link" />
        <limit effort="0.01752" velocity="293.215" lower="-0.523599" upper="0.523599" />
    </joint>
    <joint name="REyePitch_joint" type="revolute">
        <origin xyz="0 0 0" rpy="0 -0 0" />
        <axis xyz="0 1 0" />
        <parent link="REyeYaw_link" />
        <child link="REyePitch_link" />
        <limit effort="0.01752" velocity="293.215" lower="-0.349066" upper="0.349066" />
    </joint>
    <joint name="LShoulderPitch_joint" type="revolute">
        <origin xyz="0.049862 0.19 0.073851" rpy="1.49012e-08 7.45058e-09 0" />
        <axis xyz="0.417025 0.895055 -0.15801" />
        <parent link="Torso_link" />
        <child link="LShoulderPitch_link" />
        <limit effort="19.095" velocity="2.2" lower="-1.3491" upper="2.2462" />
    </joint>
    <joint name="LShoulderYaw_joint" type="revolute">
        <origin xyz="0 0 0" rpy="2.98023e-08 1.11759e-08 -5.58793e-08" />
        <axis xyz="0.0401398 0.155542 0.987013" />
        <parent link="LShoulderPitch_link" />
        <child link="LShoulderYaw_link" />
        <limit effort="9.031" velocity="4" lower="-0.5768" upper="0.9242" />
    </joint>
    <joint name="LElbowRoll_joint" type="revolute">
        <origin xyz="0.210824 7.40511e-09 -0.008631" rpy="-2.56114e-09 -0 -9.31322e-09" />
        <axis xyz="0.998889 0.0139984 0.044995" />
        <parent link="LShoulderYaw_link" />
        <child link="LElbowRoll_link" />
        <limit effort="7.404" velocity="3.7" lower="-2.2148" upper="1.9042" />
    </joint>
    <joint name="LElbowYaw_joint" type="revolute">
        <origin xyz="0 0 0" rpy="-1.49504e-08 -1.86264e-08 2.12577e-09" />
        <axis xyz="-0.0449994 0 0.998987" />
        <parent link="LElbowRoll_link" />
        <child link="LElbowYaw_link" />
        <limit effort="6.02" velocity="4" lower="-1.5228" upper="0.0044" />
    </joint>
    <joint name="LWristRoll_joint" type="revolute">
        <origin xyz="0.190404 -4.65661e-10 0.008631" rpy="1.6234e-11 -7.45058e-09 9.32998e-10" />
        <axis xyz="0.998987 0 0.0449994" />
        <parent link="LElbowYaw_link" />
        <child link="LWristRoll_link" />
        <limit effort="2.177" velocity="1.1" lower="-3.6303" upper="0.4887" />
    </joint>
    <joint name="LWristYaw_joint" type="revolute">
        <origin xyz="0 0 0" rpy="0 -0 0" />
        <axis xyz="-0.0449994 0 0.998987" />
        <parent link="LWristRoll_link" />
        <child link="LWristYaw_link" />
        <limit effort="0.862" velocity="2.26" lower="-0.4014" upper="0.4014" />
    </joint>
    <joint name="LWristPitch_joint" type="revolute">
        <origin xyz="0 0 0" rpy="0 -0 0" />
        <axis xyz="0 1 0" />
        <parent link="LWristYaw_link" />
        <child link="LWristPitch_link" />
        <limit effort="0.6" velocity="3.75" lower="-0.988" upper="0.8969" />
    </joint>
   
    <joint name="RShoulderPitch_joint" type="revolute">
        <origin xyz="0.049862 -0.19 0.073851" rpy="-1.49012e-08 7.45058e-09 0" />
        <axis xyz="-0.417025 0.895055 0.15801" />
        <parent link="Torso_link" />
        <child link="RShoulderPitch_link" />
        <limit effort="19.095" velocity="2.2" lower="-1.4554" upper="2.1399" />
    </joint>
    <joint name="RShoulderYaw_joint" type="revolute">
        <origin xyz="0 0 0" rpy="-2.98023e-08 1.49012e-08 -6.42613e-08" />
        <axis xyz="0.0401398 -0.155542 0.987014" />
        <parent link="RShoulderPitch_link" />
        <child link="RShoulderYaw_link" />
        <limit effort="9.031" velocity="4" lower="-1.0985" upper="0.4025" />
    </joint>
    <joint name="RElbowRoll_joint" type="revolute">
        <origin xyz="0.210824 -1.48548e-08 -0.008631" rpy="6.69388e-09 7.45058e-09 -7.91624e-08" />
        <axis xyz="0.998889 -0.0139984 0.044995" />
        <parent link="RShoulderYaw_link" />
        <child link="RElbowRoll_link" />
        <limit effort="7.404" velocity="3.7" lower="-1.9047" upper="2.2143" />
    </joint>
    <joint name="RElbowYaw_joint" type="revolute">
        <origin xyz="0 0 0" rpy="1.49504e-08 -1.86264e-08 -2.12577e-09" />
        <axis xyz="-0.0449994 0 0.998987" />
        <parent link="RElbowRoll_link" />
        <child link="RElbowYaw_link" />
        <limit effort="6.02" velocity="4" lower="-0.0047" upper="1.5225" />
    </joint>
    <joint name="RWristRoll_joint" type="revolute">
        <origin xyz="0.190404 4.65661e-10 0.008631" rpy="-1.6234e-11 -7.45058e-09 -9.32998e-10" />
        <axis xyz="0.998987 0 0.0449994" />
        <parent link="RElbowYaw_link" />
        <child link="RWristRoll_link" />
        <limit effort="2.177" velocity="1.1" lower="-0.4887" upper="3.6303" />
    </joint>
    <joint name="RWristYaw_joint" type="revolute">
        <origin xyz="0 0 0" rpy="0 -0 0" />
        <axis xyz="-0.0449994 0 0.998987" />
        <parent link="RWristRoll_link" />
        <child link="RWristYaw_link" />
        <limit effort="0.862" velocity="2.26" lower="-0.4014" upper="0.4014" />
    </joint>
    <joint name="RWristPitch_joint" type="revolute">
        <origin xyz="0 0 0" rpy="0 -0 0" />
        <axis xyz="0 1 0" />
        <parent link="RWristYaw_link" />
        <child link="RWristPitch_link" />
        <limit effort="0.6" velocity="3.75" lower="-0.9868" upper="0.8981" />
    </joint>
    

</robot>
